<?xml version="1.0" encoding="utf-8"?>
<!-- Revolute-Revolute Manipulator -->
<robot name="rat20_movil">
  <!-- ros_control plugin -->
 <gazebo>
    <plugin name="gazebo_ros_control" filename="libgazebo_ros_control.so">
      <robotNamespace>/rat20_movil</robotNamespace>
      <robotSimType>gazebo_ros_control/DefaultRobotHWSim</robotSimType>
    </plugin>
  </gazebo>
  <!-- Link -->
  <gazebo reference="link">
  </gazebo>
  <!-- Link1 -->
  <gazebo reference="link1">
    <mu1>0.2</mu1>
    <mu2>0.2</mu2>
    <material>Gazebo/Grey</material>
  </gazebo>
  <!-- Link2 -->
  <gazebo reference="link2">
    <mu1>0.2</mu1>
    <mu2>0.2</mu2>
    <material>Gazebo/Grey</material>
  </gazebo>
  <!-- Link3 -->
  <gazebo reference="link3">
    <mu1>0.2</mu1>
    <mu2>0.2</mu2>
    <material>Gazebo/Grey</material>
  </gazebo>
  <!-- Link4 -->
  <gazebo reference="link4">
    <mu1>0.2</mu1>
    <mu2>0.2</mu2>
    <material>Gazebo/Grey</material>
  </gazebo>
  <!-- Link5 -->
  <gazebo reference="link5">
    <mu1>0.2</mu1>
    <mu2>0.2</mu2>
    <material>Gazebo/Grey</material>
  </gazebo>
  <!-- Link6 -->
  <gazebo reference="link6">
    <mu1>0.2</mu1>
    <mu2>0.2</mu2>
    <material>Gazebo/Grey</material>
  </gazebo>
  <!-- esfera1 -->
  <gazebo reference="esfera">
  </gazebo>
  <!-- Plano -->
  <gazebo reference="plano">
  </gazebo>
  <!-- End Link -->
  <gazebo reference="end_link">
    <mu1>0.2</mu1>
    <mu2>0.2</mu2>
    <material>Gazebo/Grey</material>
  </gazebo>
  <!-- World -->
  <gazebo reference="world">
    <mu1>0.2</mu1>
    <mu2>0.2</mu2>
    <material>Gazebo/Grey</material>
  </gazebo>
  <!-- Link7 -->
  <gazebo reference="link7">
    <mu1>0.2</mu1>
    <mu2>0.2</mu2>
    <material>Gazebo/Grey</material>
  </gazebo>
  <!-- Link8 -->
  <gazebo reference="link8">
    <mu1>0.2</mu1>
    <mu2>0.2</mu2>
    <material>Gazebo/Grey</material>
  </gazebo>
  <!-- Link9 -->
  <gazebo reference="link9">
    <mu1>0.2</mu1>
    <mu2>0.2</mu2>
    <material>Gazebo/Grey</material>
  </gazebo>
  <!-- Link10-->
  <gazebo reference="link10">
    <mu1>0.2</mu1>
    <mu2>0.2</mu2>
    <material>Gazebo/Grey</material>
  </gazebo>
  <!-- Link11 -->
  <gazebo reference="link11">
    <mu1>0.2</mu1>
    <mu2>0.2</mu2>
    <material>Gazebo/Grey</material>
  </gazebo>
  <!-- Link12 -->
  <gazebo reference="link12">
    <mu1>0.2</mu1>
    <mu2>0.2</mu2>
    <material>Gazebo/Grey</material>
  </gazebo>
  <!-- End Link1 -->
  <gazebo reference="end_link1">
    <mu1>0.2</mu1>
    <mu2>0.2</mu2>
    <material>Gazebo/Grey</material>
  </gazebo>
  <!-- rh_p12_rn_base -->
  <gazebo reference="rh_p12_rn_base">
    <mu1>0.2</mu1>
    <mu2>0.2</mu2>
    <material>Gazebo/Grey</material>
  </gazebo>
  <!-- rh_p12_rn_r1 -->
  <gazebo reference="rh_p12_rn_r1">
    <mu1>0.2</mu1>
    <mu2>0.2</mu2>
    <material>Gazebo/Grey</material>
  </gazebo>
  <!-- rh_p12_rn_r2 -->
  <gazebo reference="rh_p12_rn_r2">
    <mu1>0.2</mu1>
    <mu2>0.2</mu2>
    <material>Gazebo/Grey</material>
  </gazebo>
  <!-- rh_p12_rn_l1 -->
  <gazebo reference="rh_p12_rn_l1">
    <mu1>0.2</mu1>
    <mu2>0.2</mu2>
    <material>Gazebo/Grey</material>
  </gazebo>
  <!-- rh_p12_rn_l2 -->
  <gazebo reference="rh_p12_rn_l2">
    <mu1>0.2</mu1>
    <mu2>0.2</mu2>
    <material>Gazebo/Grey</material>
  </gazebo>
  <!-- rh_p12_rn_base_izq-->
  <gazebo reference="rh_p12_rn_base_izq">
    <mu1>0.2</mu1>
    <mu2>0.2</mu2>
    <material>Gazebo/Grey</material>
  </gazebo>
  <!-- rh_p12_rn_r1 -->
  <gazebo reference="rh_p12_rn_r1_izq">
    <mu1>0.2</mu1>
    <mu2>0.2</mu2>
    <material>Gazebo/Grey</material>
  </gazebo>
  <!-- rh_p12_rn_r2 -->
  <gazebo reference="rh_p12_rn_r2_izq">
    <mu1>0.2</mu1>
    <mu2>0.2</mu2>
    <material>Gazebo/Grey</material>
  </gazebo>
  <!-- rh_p12_rn_l1 -->
  <gazebo reference="rh_p12_rn_l1_izq">
    <mu1>0.2</mu1>
    <mu2>0.2</mu2>
    <material>Gazebo/Grey</material>
  </gazebo>
  <!-- rh_p12_rn_l2 -->
  <gazebo reference="rh_p12_rn_l2_izq">
    <mu1>0.2</mu1>
    <mu2>0.2</mu2>
    <material>Gazebo/Grey</material>
  </gazebo>
  <!-- World1 -->
  <gazebo reference="world1">
  </gazebo>
  <!--chasis-->
  <gazebo reference="chasis">
    <material value="Gazebo/Grey"/>
  </gazebo>
  <!--rueda1 -->
  <gazebo reference="rueda1">
    <mu1>0.2</mu1>
    <mu2>0.2</mu2>
    <material>Gazebo/Grey</material>
  </gazebo>
  <!--rueda2-->
  <gazebo reference="rueda2">
    <mu1>0.2</mu1>
    <mu2>0.2</mu2>
    <material>Gazebo/Grey</material>
  </gazebo>
  <!--rueda3-->
  <gazebo reference="rueda3">
    <mu1>0.2</mu1>
    <mu2>0.2</mu2>
    <material>Gazebo/Grey</material>
  </gazebo>
  <!--rueda4 -->
  <gazebo reference="rueda4">
    <mu1>0.2</mu1>
    <mu2>0.2</mu2>
    <material>Gazebo/Grey</material>
  </gazebo>
  <!--base1 -->
  <gazebo reference="base1">
    <mu1>0.2</mu1>
    <mu2>0.2</mu2>
    <material>Gazebo/Grey</material>
  </gazebo>
  <gazebo reference="torso">
    <mu1>0.2</mu1>
    <mu2>0.2</mu2>
    <material>Gazebo/Grey</material>
  </gazebo>
  <gazebo reference="accion_lineal">
    <mu1>0.2</mu1>
    <mu2>0.2</mu2>
    <material>Gazebo/Grey</material>
  </gazebo>
 <gazebo reference="motor_lineal">
    <mu1>0.2</mu1>
    <mu2>0.2</mu2>
    <material>Gazebo/Grey</material>
  </gazebo>
 <gazebo reference="perno">
    <mu1>0.2</mu1>
    <mu2>0.2</mu2>
    <material>Gazebo/Grey</material>
  </gazebo>
  <material name="black">
    <color rgba="0.0 0.0 0.0 1.0"/>
  </material>
  <material name="blue">
    <color rgba="0.0 0.0 0.8 1.0"/>
  </material>
  <material name="green">
    <color rgba="0.0 0.8 0.0 1.0"/>
  </material>
  <material name="grey">
    <color rgba="0.2 0.2 0.2 1.0"/>
  </material>
  <material name="orange">
    <color rgba="1.0 0.423529411765 0.0392156862745 1.0"/>
  </material>
  <material name="brown">
    <color rgba="0.870588235294 0.811764705882 0.764705882353 1.0"/>
  </material>
  <material name="red">
    <color rgba="0.8 0.0 0.0 1.0"/>
  </material>
  <material name="white">
    <color rgba="1.0 1.0 1.0 1.0"/>
  </material>
  <!-- Used for fixing robot to Gazebo 'link 1' -->
  <link name="world">
    <inertial>
      <origin rpy="0 0 0" xyz="0 0 0"/>
      <!--<origin xyz="0.00023 0.00000 -0.06377" rpy="0 0 0"/>-->
      <mass value="10000"/>
      <inertia ixx="10.0" ixy="0.0" ixz="0.0" iyy="10.0" iyz="0.0" izz="10.0"/>
      <!--<inertia ixx="0.00121064" ixy="0.0" ixz="0.00001100" iyy="0.00120886" iyz="0.0" izz="0.00038103" />-->
    </inertial>
  </link>
  <joint name="world_fixed" type="fixed">
    <origin rpy="0 -1.57 0" xyz="-0.014 0.19 0"/>
    <parent link="torso"/>
    <child link="link1"/>
  </joint>
  <!-- link 1 -->
  <link name="link1">
    <collision>
      <origin rpy="0 0 0" xyz="0 0 0"/>
      <geometry>
        <mesh filename="package://rat20_movil/meshes/link_1.stl" scale="0.001 0.001 0.001"/>
      </geometry>
    </collision>
    <visual>
      <origin rpy="0 0 0" xyz="0 0 0"/>
      <geometry>
        <mesh filename="package://rat20_movil/meshes/link_1.stl" scale="0.001 0.001 0.001"/>
      </geometry>
      <material name="grey"/>
    </visual>
    <inertial>
      <origin rpy="0 0 0" xyz="0.00023 0.00000 0.06223"/>
      <!--<origin xyz="0.00023 0.00000 -0.06377" rpy="0 0 0"/>-->
      <mass value="0.85644"/>
      <inertia ixx="1.0" ixy="0.0" ixz="0.0" iyy="1.0" iyz="0.0" izz="1.0"/>
      <!--<inertia ixx="0.00121064" ixy="0.0" ixz="0.00001100" iyy="0.00120886" iyz="0.0" izz="0.00038103" />-->
    </inertial>
  </link>
  <!-- Joint 1 -->
  <joint name="joint1" type="revolute">
    <parent link="link1"/>
    <child link="link2"/>
    <origin rpy="0 0 0" xyz="0.0 0.0 0.126"/>
    <axis xyz="0 0 1"/>
    <limit effort="1000" lower="-1.570796327" upper="1.570796327" velocity="6.5"/>
    <dynamics damping="80"/>
  </joint>
  <transmission name="tran1">
    <type>transmission_interface/SimpleTransmission</type>
    <joint name="joint1">
      <hardwareInterface>EffortJointInterface</hardwareInterface>
    </joint>
    <actuator name="motor1">
      <hardwareInterface>EffortJointInterface</hardwareInterface>
      <mechanicalReduction>1</mechanicalReduction>
    </actuator>
  </transmission>
  <!-- link  2 -->
  <link name="link2">
    <collision>
      <origin rpy="0 0 0" xyz="0 0 0"/>
      <geometry>
        <mesh filename="package://rat20_movil/meshes/link_2.stl" scale="0.001 0.001 0.001"/>
      </geometry>
    </collision>
    <visual>
      <origin rpy="0 0 0" xyz="0 0 0"/>
      <geometry>
        <mesh filename="package://rat20_movil/meshes/link_2.stl" scale="0.001 0.001 0.001"/>
      </geometry>
      <material name="grey"/>
    </visual>
    <inertial>
      <origin rpy="0 0 0" xyz="0.00000 0.00080 0.03183"/>
      <!--<origin xyz="0.00000 -0.06820 -0.00117" rpy="0 0 0"/>-->
      <mass value="0.94658"/>
      <inertia ixx="1.0" ixy="0.0" ixz="0.0" iyy="1.0" iyz="0.0" izz="1.0"/>
      <!--<inertia ixx="0.00152547" ixy="0.0" ixz="0.0" iyy="0.00045954" iyz="-0.00001086" izz="0.00151740" />-->
    </inertial>
  </link>
  <!-- Joint 2 -->
  <joint name="joint2" type="revolute">
    <parent link="link2"/>
    <child link="link3"/>
    <origin rpy="0 0 0" xyz="0.0 0.069 0.033"/>
    <axis xyz="0 1 0"/>
    <limit effort="1000" lower="-1.570796327" upper="1.570796327" velocity="6.5"/>
    <dynamics damping="80"/>
  </joint>
  <transmission name="tran2">
    <type>transmission_interface/SimpleTransmission</type>
    <joint name="joint2">
      <hardwareInterface>EffortJointInterface</hardwareInterface>
    </joint>
    <actuator name="motor2">
      <hardwareInterface>EffortJointInterface</hardwareInterface>
      <mechanicalReduction>1</mechanicalReduction>
    </actuator>
  </transmission>
  <!-- link 3 -->
  <link name="link3">
    <collision>
      <origin rpy="0 0 0" xyz="0 0 0"/>
      <geometry>
        <mesh filename="package://rat20_movil/meshes/link_3.stl" scale="0.001 0.001 0.001"/>
      </geometry>
    </collision>
    <visual>
      <origin rpy="0 0 0" xyz="0 0 0"/>
      <geometry>
        <mesh filename="package://rat20_movil/meshes/link_3.stl" scale="0.001 0.001 0.001"/>
      </geometry>
      <material name="grey"/>
    </visual>
    <inertial>
      <origin rpy="0 0 0" xyz="0.01768 -0.06881 0.20524"/>
      <!--<origin xyz="-0.01232 -0.05731 -0.05876" rpy="0 0 0"/>-->
      <mass value="1.30260"/>
      <inertia ixx="1.0" ixy="0.0" ixz="0.0" iyy="1.0" iyz="0.0" izz="1.0"/>
      <!--<inertia ixx="0.01111021" ixy="0.00001331" ixz="-0.00134208" iyy="0.01046642" iyz="0.00016235" izz="0.00202081" />-->
    </inertial>
  </link>
  <!-- Joint 3 -->
  <joint name="joint3" type="revolute">
    <parent link="link3"/>
    <child link="link4"/>
    <origin rpy="0 0 0" xyz="0.03000 -0.01150 0.26400"/>
    <axis xyz="0 1 0"/>
    <limit effort="1000" lower="-1.570796327" upper="1.570796327" velocity="6.5"/>
    <dynamics damping="80"/>
  </joint>
  <transmission name="tran3">
    <type>transmission_interface/SimpleTransmission</type>
    <joint name="joint3">
      <hardwareInterface>EffortJointInterface</hardwareInterface>
    </joint>
    <actuator name="motor3">
      <hardwareInterface>EffortJointInterface</hardwareInterface>
      <mechanicalReduction>1</mechanicalReduction>
    </actuator>
  </transmission>
  <!-- link 4 -->
  <link name="link4">
    <collision>
      <origin rpy="0 0 0" xyz="0 0 0"/>
      <geometry>
        <mesh filename="package://rat20_movil/meshes/link_4.stl" scale="0.001 0.001 0.001"/>
      </geometry>
    </collision>
    <visual>
      <origin rpy="0 0 0" xyz="0 0 0"/>
      <geometry>
        <mesh filename="package://rat20_movil/meshes/link_4.stl" scale="0.001 0.001 0.001"/>
      </geometry>
      <material name="grey"/>
    </visual>
    <inertial>
      <origin rpy="0 0 0" xyz="0.12475 -0.05716 0.02979"/>
      <!--<origin xyz="-0.07025 0.00034 -0.00021" rpy="0 0 0"/>-->
      <mass value="1.15977"/>
      <inertia ixx="1.0" ixy="0.0" ixz="0.0" iyy="1.0" iyz="0.0" izz="1.0"/>
      <!--<inertia ixx="0.00096726" ixy="0.00004383" ixz="-0.00002771" iyy="0.00318801" iyz="0.00000627" izz="0.00341484" />-->
    </inertial>
  </link>
  <!-- Joint 4 -->
  <joint name="joint4" type="revolute">
    <parent link="link4"/>
    <child link="link5"/>
    <origin rpy="0 0 0" xyz="0.19500 -0.05750 0.03000"/>
    <axis xyz="1 0 0"/>
    <limit effort="1000" lower="-1.570796327" upper="1.570796327" velocity="6.5"/>
    <dynamics damping="80"/>
  </joint>
  <transmission name="tran4">
    <type>transmission_interface/SimpleTransmission</type>
    <joint name="joint4">
      <hardwareInterface>EffortJointInterface</hardwareInterface>
    </joint>
    <actuator name="motor4">
      <hardwareInterface>EffortJointInterface</hardwareInterface>
      <mechanicalReduction>1</mechanicalReduction>
    </actuator>
  </transmission>
  <!-- link 5 -->
  <link name="link5">
    <collision>
      <origin rpy="0 0 0" xyz="0 0 0"/>
      <geometry>
        <mesh filename="package://rat20_movil/meshes/link_5.stl" scale="0.001 0.001 0.001"/>
      </geometry>
    </collision>
    <visual>
      <origin rpy="0 0 0" xyz="0 0 0"/>
      <geometry>
        <mesh filename="package://rat20_movil/meshes/link_5.stl" scale="0.001 0.001 0.001"/>
      </geometry>
      <material name="grey"/>
    </visual>
    <inertial>
      <origin rpy="0 0 0" xyz="0.05642 -0.00217 0.00002"/>
      <!--<origin xyz="-0.00658 -0.04717 0.00002" rpy="0 0 0"/>-->
      <mass value="0.44688"/>
      <inertia ixx="1.0" ixy="0.0" ixz="0.0" iyy="1.0" iyz="0.0" izz="1.0"/>
      <!--<inertia ixx="0.00030285" ixy="0.00000761" ixz="0.00000031" iyy="0.00022339" iyz="-0.00000001" izz="0.00039766" />-->
    </inertial>
  </link>
  <!-- Joint 5 -->
  <joint name="joint5" type="revolute">
    <parent link="link5"/>
    <child link="link6"/>
    <origin rpy="0 0 0" xyz="0.06300 0.04500 0.00000"/>
    <axis xyz="0 1 0"/>
    <limit effort="1000" lower="-1.570796327" upper="1.570796327" velocity="6.5"/>
    <dynamics damping="80"/>
  </joint>
  <transmission name="tran5">
    <type>transmission_interface/SimpleTransmission</type>
    <joint name="joint5">
      <hardwareInterface>EffortJointInterface</hardwareInterface>
    </joint>
    <actuator name="motor5">
      <hardwareInterface>EffortJointInterface</hardwareInterface>
      <mechanicalReduction>1</mechanicalReduction>
    </actuator>
  </transmission>
  <!-- link 6 -->
  <link name="link6">
    <collision>
      <origin rpy="0 0 0" xyz="0 0 0"/>
      <geometry>
        <mesh filename="package://rat20_movil/meshes/link_6.stl" scale="0.001 0.001 0.001"/>
      </geometry>
    </collision>
    <visual>
      <origin rpy="0 0 0" xyz="0 0 0"/>
      <geometry>
        <mesh filename="package://rat20_movil/meshes/link_6.stl" scale="0.001 0.001 0.001"/>
      </geometry>
      <material name="grey"/>
    </visual>
    <inertial>
      <origin rpy="0 0 0" xyz="0.06831 -0.04457 0.00000"/>
      <!--<origin xyz="-0.05469 0.00043 0.00000" rpy="0 0 0"/>-->
      <mass value="0.43273"/>
      <inertia ixx="1.0" ixy="0.0" ixz="0.0" iyy="1.0" iyz="0.0" izz="1.0"/>
      <!--<inertia ixx="0.00021512" ixy="0.00001009" ixz="0.00000000" iyy="0.00042827" iyz="0.00000000" izz="0.00051436" />-->
    </inertial>
  </link>
  <!-- Joint 6 -->
  <joint name="joint6" type="revolute">
    <parent link="link6"/>
    <child link="end_link"/>
    <origin rpy="0 0 0" xyz="0.12300 -0.04500 0.00000"/>
    <axis xyz="1 0 0"/>
    <limit effort="1000" lower="-1.570796327" upper="1.570796327" velocity="6.5"/>
    <dynamics damping="80"/>
  </joint>
  <transmission name="tran6">
    <type>transmission_interface/SimpleTransmission</type>
    <joint name="joint6">
      <hardwareInterface>EffortJointInterface</hardwareInterface>
    </joint>
    <actuator name="motor6">
      <hardwareInterface>EffortJointInterface</hardwareInterface>
      <mechanicalReduction>1</mechanicalReduction>
    </actuator>
  </transmission>
  <!-- end link -->
  <link name="end_link">
    <collision>
      <origin rpy="0 0 0" xyz="0 0 0"/>
      <geometry>
        <mesh filename="package://rat20_movil/meshes/end_link.stl" scale="0.001 0.001 0.001"/>
      </geometry>
    </collision>
    <visual>
      <origin rpy="0 0 0" xyz="0 0 0"/>
      <geometry>
        <mesh filename="package://rat20_movil/meshes/end_link.stl" scale="0.001 0.001 0.001"/>
      </geometry>
      <material name="grey"/>
    </visual>
    <inertial>
      <origin rpy="0 0 0" xyz="0.00337 0.00000 0.00000"/>
      <mass value="0.01919"/>
      <inertia ixx="1.0" ixy="0.0" ixz="0.0" iyy="1.0" iyz="0.0" izz="1.0"/>
      <!--<inertia ixx="0.00000938" ixy="0.0" ixz="0.0" iyy="0.00000338" iyz="0.0" izz="0.00000635" />-->
    </inertial>
  </link>
  <joint name="joint14" type="fixed">
    <origin rpy="-1.57 0 -1.57" xyz="0 0 0"/>
    <parent link="end_link"/>
    <child link="rh_p12_rn_base"/>
  </joint>
  <!-- base -->
  <link name="rh_p12_rn_base">
    <collision>
      <origin rpy="0 0 0" xyz="0 0 0"/>
      <geometry>
        <mesh filename="package://rat20_movil/meshes/base.stl" scale="0.001 0.001 0.001"/>
      </geometry>
    </collision>
    <visual>
      <origin rpy="0 0 0" xyz="0 0 0"/>
      <geometry>
        <mesh filename="package://rat20_movil/meshes/base.stl" scale="0.001 0.001 0.001"/>
      </geometry>
      <material name="grey"/>
    </visual>
    <inertial>
      <origin rpy="0 0 0" xyz="0.000 0.000 0.032"/>
      <mass value="0.236"/>
      <!--<inertia ixx="0.00017" ixy="0.0" ixz="0.0" iyy="0.00011" iyz="0.0" izz="0.00017" />-->
      <inertia ixx="1.0" ixy="0.0" ixz="0.0" iyy="1.0" iyz="0.0" izz="1.0"/>
    </inertial>
  </link>
  <!-- Joint -->
  <joint name="rh_p12_rn" type="revolute">
    <parent link="rh_p12_rn_base"/>
    <child link="rh_p12_rn_r1"/>
    <origin rpy="0 0 0" xyz="0.0 0.008 0.048"/>
    <axis xyz="1 0 0"/>
    <limit effort="1000" lower="0.0" upper="1.1" velocity="6.5"/>
    <dynamics damping="0.7"/>
  </joint>
  <transmission name="tran_r1">
    <type>transmission_interface/SimpleTransmission</type>
    <joint name="rh_p12_rn">
      <hardwareInterface>hardware_interface/EffortJointInterface</hardwareInterface>
    </joint>
    <actuator name="motor_r1">
      <hardwareInterface>hardware_interface/EffortJointInterface</hardwareInterface>
      <mechanicalReduction>1</mechanicalReduction>
    </actuator>
  </transmission>
  <!-- rh_p12_rn_r1 -->
  <link name="rh_p12_rn_r1">
    <collision>
      <origin rpy="0 0 0" xyz="0 0 0"/>
      <geometry>
        <mesh filename="package://rat20_movil/meshes/r1.stl" scale="0.001 0.001 0.001"/>
      </geometry>
    </collision>
    <visual>
      <origin rpy="0 0 0" xyz="0 0 0"/>
      <geometry>
        <mesh filename="package://rat20_movil/meshes/r1.stl" scale="0.001 0.001 0.001"/>
      </geometry>
      <material name="grey"/>
    </visual>
    <inertial>
      <origin rpy="0 0 0" xyz="0.000 0.034 0.004"/>
      <mass value="0.068"/>
      <!--<inertia ixx="0.00004" ixy="0.0" ixz="0.0" iyy="0.00002" iyz="-0.00001" izz="0.00002" />-->
      <inertia ixx="1.0" ixy="0.0" ixz="0.0" iyy="1.0" iyz="0.0" izz="1.0"/>
    </inertial>
  </link>
  <!-- Right Joint 2 -->
  <joint name="rh_r2" type="revolute">
    <parent link="rh_p12_rn_r1"/>
    <child link="rh_p12_rn_r2"/>
    <origin rpy="0 0 0" xyz="0.0 0.0493634 0.0285"/>
    <axis xyz="-1 0 0"/>
    <limit effort="1000" lower="0.0" upper="1.0" velocity="6.5"/>
    <dynamics damping="0.7"/>
  </joint>
  <transmission name="tran_r2">
    <type>transmission_interface/SimpleTransmission</type>
    <joint name="rh_r2">
      <hardwareInterface>hardware_interface/EffortJointInterface</hardwareInterface>
    </joint>
    <actuator name="motor_r2">
      <hardwareInterface>hardware_interface/EffortJointInterface</hardwareInterface>
      <mechanicalReduction>1</mechanicalReduction>
    </actuator>
  </transmission>
  <!-- rh_p12_rn_r2 -->
  <link name="rh_p12_rn_r2">
    <collision>
      <origin rpy="0 0 0" xyz="0 0 0"/>
      <geometry>
        <mesh filename="package://rat20_movil/meshes/r2.stl" scale="0.001 0.001 0.001"/>
      </geometry>
    </collision>
    <visual>
      <origin rpy="0 0 0" xyz="0 0 0"/>
      <geometry>
        <mesh filename="package://rat20_movil/meshes/r2.stl" scale="0.001 0.001 0.001"/>
      </geometry>
      <material name="grey"/>
    </visual>
    <inertial>
      <origin rpy="0 0 0" xyz="0.000 0.006 0.011"/>
      <mass value="0.022"/>
      <!--<inertia ixx="0.0" ixy="0.0" ixz="0.0" iyy="0.00001" iyz="0.0" izz="0.0" />-->
      <inertia ixx="1.0" ixy="0.0" ixz="0.0" iyy="1.0" iyz="0.0" izz="1.0"/>
    </inertial>
  </link>
  <!-- Left Joint 1 -->
  <joint name="rh_l1" type="revolute">
    <parent link="rh_p12_rn_base"/>
    <child link="rh_p12_rn_l1"/>
    <origin rpy="0 0 0" xyz="0.0 -0.008 0.048"/>
    <axis xyz="-1 0 0"/>
    <limit effort="1000" lower="0.0" upper="1.1" velocity="6.5"/>
    <dynamics damping="0.7"/>
  </joint>
  <transmission name="tran_l1">
    <type>transmission_interface/SimpleTransmission</type>
    <joint name="rh_l1">
      <hardwareInterface>hardware_interface/EffortJointInterface</hardwareInterface>
    </joint>
    <actuator name="motor_l1">
      <hardwareInterface>hardware_interface/EffortJointInterface</hardwareInterface>
      <mechanicalReduction>1</mechanicalReduction>
    </actuator>
  </transmission>
  <!-- rh_p12_rn_l1 -->
  <link name="rh_p12_rn_l1">
    <collision>
      <origin rpy="0 0 0" xyz="0 0 0"/>
      <geometry>
        <mesh filename="package://rat20_movil/meshes/l1.stl" scale="0.001 0.001 0.001"/>
      </geometry>
    </collision>
    <visual>
      <origin rpy="0 0 0" xyz="0 0 0"/>
      <geometry>
        <mesh filename="package://rat20_movil/meshes/l1.stl" scale="0.001 0.001 0.001"/>
      </geometry>
      <material name="grey"/>
    </visual>
    <inertial>
      <origin rpy="0 0 0" xyz="0.000 -0.034 0.004"/>
      <mass value="0.068"/>
      <!--<inertia ixx="0.00004" ixy="0.0" ixz="0.0" iyy="0.00002" iyz="0.00001" izz="0.00002" />-->
      <inertia ixx="1.0" ixy="0.0" ixz="0.0" iyy="1.0" iyz="0.0" izz="1.0"/>
    </inertial>
  </link>
  <!-- Left Joint 2 -->
  <joint name="rh_l2" type="revolute">
    <parent link="rh_p12_rn_l1"/>
    <child link="rh_p12_rn_l2"/>
    <origin rpy="0 0 0" xyz="0.0 -0.0493634 0.0285"/>
    <axis xyz="1 0 0"/>
    <limit effort="1000" lower="0.0" upper="1.0" velocity="6.5"/>
    <dynamics damping="0.7"/>
  </joint>
  <transmission name="tran_l2">
    <type>transmission_interface/SimpleTransmission</type>
    <joint name="rh_l2">
      <hardwareInterface>hardware_interface/EffortJointInterface</hardwareInterface>
    </joint>
    <actuator name="motor_l2">
      <hardwareInterface>hardware_interface/EffortJointInterface</hardwareInterface>
      <mechanicalReduction>1</mechanicalReduction>
    </actuator>
  </transmission>
  <!-- rh_p12_rn_l2 -->
  <link name="rh_p12_rn_l2">
    <collision>
      <origin rpy="0 0 0" xyz="0 0 0"/>
      <geometry>
        <mesh filename="package://rat20_movil/meshes/l2.stl" scale="0.001 0.001 0.001"/>
      </geometry>
    </collision>
    <visual>
      <origin rpy="0 0 0" xyz="0 0 0"/>
      <geometry>
        <mesh filename="package://rat20_movil/meshes/l2.stl" scale="0.001 0.001 0.001"/>
      </geometry>
      <material name="grey"/>
    </visual>
    <inertial>
      <origin rpy="0 0 0" xyz="0.000 -0.006 0.011"/>
      <mass value="0.022"/>
      <!--<inertia ixx="0.0" ixy="0.0" ixz="0.0" iyy="0.00001" iyz="0.0" izz="0.0" />-->
      <inertia ixx="1.0" ixy="0.0" ixz="0.0" iyy="1.0" iyz="0.0" izz="1.0"/>
    </inertial>
  </link>
  <!-- esfera
  <link name="esfera">
<collision>
      <origin xyz="0 0 0" rpy="0 0 0"/>
      <geometry>
         <mesh filename="package://rat20_movil/meshes/Pieza1.stl" scale="0.1 0.1 0.1"/>
      </geometry>
    </collision>

    <visual>
      <origin xyz="0 0 0" rpy="0 0 0"/>
      <geometry>
         <mesh filename="package://rat20_movil/meshes/Pieza1.stl" scale="0.1 0.1 0.1"/>
      </geometry>
      <material name="grey"/>
    </visual>
  </link>

  <joint name="esfera1" type="fixed">
    <origin xyz="0 0 0" rpy="0 0 0"/>
    <parent link="end_link"/>
    <child link="esfera"/>
  </joint>

esfera1-->
  <!--  <link name="esfera3">
<collision>
      <origin xyz="0.15 -0.060 0.03" rpy="0 0 0"/>
      <geometry>
        <mesh filename="package://rat20_movil/meshes/Pieza1.stl" scale="0.1 0.1 0.1"/>
      </geometry>
    </collision>

    <visual>
      <origin xyz="0.15 -0.060 0.03" rpy="0 0 0"/>
      <geometry>
         <mesh filename="package://rat20_movil/meshes/Pieza1.stl" scale="0.1 0.1 0.1"/>
      </geometry>
      <material name="grey"/>
    </visual>
  </link>


  <joint name="esfera2" type="fixed">
    <origin xyz="0 0 0" rpy="0 0 0"/>
    <parent link="link4"/>
    <child link="esfera3"/>
  </joint>-->
  <!-- esfera2
  <link name="esfera5">
<collision>
      <origin xyz="0 -0.08 0.15" rpy="0 0 0"/>
      <geometry>
        <mesh filename="package://rat20_movil/meshes/Pieza1.stl" scale="0.1 0.1 0.1"/>
      </geometry>
    </collision>

    <visual>
      <origin xyz="0 -0.08 0.15" rpy="0 0 0"/>
      <geometry>
        <mesh filename="package://rat20_movil/meshes/Pieza1.stl" scale="0.1 0.1 0.1"/>
      </geometry>
      <material name="grey"/>
    </visual>
  </link>


  <joint name="esfera6" type="fixed">
    <origin xyz="0 0 0" rpy="0 0 0"/>
    <parent link="link3"/>
    <child link="esfera5"/>
  </joint>-->
  <joint name="world_fixed1" type="fixed">
    <origin rpy="1.57 -1.57 1.57" xyz="0.014 0.19 0"/>
    <parent link="torso"/>
    <child link="link7"/>
  </joint>
  <!-- link 7 -->
  <link name="link7">
    <collision>
      <origin rpy="0 0 0" xyz="0 0 0"/>
      <geometry>
        <mesh filename="package://rat20_movil/meshes/link_1.stl" scale="0.001 0.001 0.001"/>
      </geometry>
    </collision>
    <visual>
      <origin rpy="0 0 0" xyz="0 0 0"/>
      <geometry>
        <mesh filename="package://rat20_movil/meshes/link_1.stl" scale="0.001 0.001 0.001"/>
      </geometry>
      <material name="grey"/>
    </visual>
    <inertial>
      <origin rpy="0 0 0" xyz="0.00023 0.00000 0.06223"/>
      <!--<origin xyz="0.00023 0.00000 -0.06377" rpy="0 0 0"/>-->
      <mass value="0.85644"/>
      <inertia ixx="1.0" ixy="0.0" ixz="0.0" iyy="1.0" iyz="0.0" izz="1.0"/>
      <!--<inertia ixx="0.00121064" ixy="0.0" ixz="0.00001100" iyy="0.00120886" iyz="0.0" izz="0.00038103" />-->
    </inertial>
  </link>
  <!-- Joint 7 -->
  <joint name="joint7" type="revolute">
    <parent link="link7"/>
    <child link="link8"/>
    <origin rpy="0 0 0" xyz="0.0 0.0 0.126"/>
    <axis xyz="0 0 1"/>
    <limit effort="1000" lower="-1.570796327" upper="1.570796327" velocity="6.5"/>
    <dynamics damping="80"/>
  </joint>
  <transmission name="tran7">
    <type>transmission_interface/SimpleTransmission</type>
    <joint name="joint7">
      <hardwareInterface>EffortJointInterface</hardwareInterface>
    </joint>
    <actuator name="motor7">
      <hardwareInterface>EffortJointInterface</hardwareInterface>
      <mechanicalReduction>1</mechanicalReduction>
    </actuator>
  </transmission>
  <!-- link  8 -->
  <link name="link8">
    <collision>
      <origin rpy="0 0 0" xyz="0 0 0"/>
      <geometry>
        <mesh filename="package://rat20_movil/meshes/link_2.stl" scale="0.001 0.001 0.001"/>
      </geometry>
    </collision>
    <visual>
      <origin rpy="0 0 0" xyz="0 0 0"/>
      <geometry>
        <mesh filename="package://rat20_movil/meshes/link_2.stl" scale="0.001 0.001 0.001"/>
      </geometry>
      <material name="grey"/>
    </visual>
    <inertial>
      <origin rpy="0 0 0" xyz="0.00000 0.00080 0.03183"/>
      <!--<origin xyz="0.00000 -0.06820 -0.00117" rpy="0 0 0"/>-->
      <mass value="0.94658"/>
      <inertia ixx="1.0" ixy="0.0" ixz="0.0" iyy="1.0" iyz="0.0" izz="1.0"/>
      <!--<inertia ixx="0.00152547" ixy="0.0" ixz="0.0" iyy="0.00045954" iyz="-0.00001086" izz="0.00151740" />-->
    </inertial>
  </link>
  <!-- Joint 8 -->
  <joint name="joint8" type="revolute">
    <parent link="link8"/>
    <child link="link9"/>
    <origin rpy="0 0 0" xyz="0.0 0.069 0.033"/>
    <axis xyz="0 1 0"/>
    <limit effort="1000" lower="-1.570796327" upper="1.570796327" velocity="6.5"/>
    <dynamics damping="80"/>
  </joint>
  <transmission name="tran8">
    <type>transmission_interface/SimpleTransmission</type>
    <joint name="joint8">
      <hardwareInterface>EffortJointInterface</hardwareInterface>
    </joint>
    <actuator name="motor8">
      <hardwareInterface>EffortJointInterface</hardwareInterface>
      <mechanicalReduction>1</mechanicalReduction>
    </actuator>
  </transmission>
  <!-- link 9 -->
  <link name="link9">
    <collision>
      <origin rpy="0 0 0" xyz="0 0 0"/>
      <geometry>
        <mesh filename="package://rat20_movil/meshes/link_3.stl" scale="0.001 0.001 0.001"/>
      </geometry>
    </collision>
    <visual>
      <origin rpy="0 0 0" xyz="0 0 0"/>
      <geometry>
        <mesh filename="package://rat20_movil/meshes/link_3.stl" scale="0.001 0.001 0.001"/>
      </geometry>
      <material name="grey"/>
    </visual>
    <inertial>
      <origin rpy="0 0 0" xyz="0.01768 -0.06881 0.20524"/>
      <!--<origin xyz="-0.01232 -0.05731 -0.05876" rpy="0 0 0"/>-->
      <mass value="1.30260"/>
      <inertia ixx="1.0" ixy="0.0" ixz="0.0" iyy="1.0" iyz="0.0" izz="1.0"/>
      <!--<inertia ixx="0.01111021" ixy="0.00001331" ixz="-0.00134208" iyy="0.01046642" iyz="0.00016235" izz="0.00202081" />-->
    </inertial>
  </link>
  <!-- Joint 9 -->
  <joint name="joint9" type="revolute">
    <parent link="link9"/>
    <child link="link10"/>
    <origin rpy="0 0 0" xyz="0.03000 -0.01150 0.26400"/>
    <axis xyz="0 1 0"/>
    <limit effort="1000" lower="-1.570796327" upper="1.570796327" velocity="6.5"/>
    <dynamics damping="80"/>
  </joint>
  <transmission name="tran9">
    <type>transmission_interface/SimpleTransmission</type>
    <joint name="joint9">
      <hardwareInterface>EffortJointInterface</hardwareInterface>
    </joint>
    <actuator name="motor9">
      <hardwareInterface>EffortJointInterface</hardwareInterface>
      <mechanicalReduction>1</mechanicalReduction>
    </actuator>
  </transmission>
  <!-- link 10 -->
  <link name="link10">
    <collision>
      <origin rpy="0 0 0" xyz="0 0 0"/>
      <geometry>
        <mesh filename="package://rat20_movil/meshes/link_4.stl" scale="0.001 0.001 0.001"/>
      </geometry>
    </collision>
    <visual>
      <origin rpy="0 0 0" xyz="0 0 0"/>
      <geometry>
        <mesh filename="package://rat20_movil/meshes/link_4.stl" scale="0.001 0.001 0.001"/>
      </geometry>
      <material name="grey"/>
    </visual>
    <inertial>
      <origin rpy="0 0 0" xyz="0.12475 -0.05716 0.02979"/>
      <!--<origin xyz="-0.07025 0.00034 -0.00021" rpy="0 0 0"/>-->
      <mass value="1.15977"/>
      <inertia ixx="1.0" ixy="0.0" ixz="0.0" iyy="1.0" iyz="0.0" izz="1.0"/>
      <!--<inertia ixx="0.00096726" ixy="0.00004383" ixz="-0.00002771" iyy="0.00318801" iyz="0.00000627" izz="0.00341484" />-->
    </inertial>
  </link>
  <!-- Joint 10 -->
  <joint name="joint10" type="revolute">
    <parent link="link10"/>
    <child link="link11"/>
    <origin rpy="0 0 0" xyz="0.19500 -0.05750 0.03000"/>
    <axis xyz="1 0 0"/>
    <limit effort="1000" lower="-1.570796327" upper="1.570796327" velocity="6.5"/>
    <dynamics damping="80"/>
  </joint>
  <transmission name="tran10">
    <type>transmission_interface/SimpleTransmission</type>
    <joint name="joint10">
      <hardwareInterface>EffortJointInterface</hardwareInterface>
    </joint>
    <actuator name="motor10">
      <hardwareInterface>EffortJointInterface</hardwareInterface>
      <mechanicalReduction>1</mechanicalReduction>
    </actuator>
  </transmission>
  <!-- link 11 -->
  <link name="link11">
    <collision>
      <origin rpy="0 0 0" xyz="0 0 0"/>
      <geometry>
        <mesh filename="package://rat20_movil/meshes/link_5.stl" scale="0.001 0.001 0.001"/>
      </geometry>
    </collision>
    <visual>
      <origin rpy="0 0 0" xyz="0 0 0"/>
      <geometry>
        <mesh filename="package://rat20_movil/meshes/link_5.stl" scale="0.001 0.001 0.001"/>
      </geometry>
      <material name="grey"/>
    </visual>
    <inertial>
      <origin rpy="0 0 0" xyz="0.05642 -0.00217 0.00002"/>
      <!--<origin xyz="-0.00658 -0.04717 0.00002" rpy="0 0 0"/>-->
      <mass value="0.44688"/>
      <inertia ixx="1.0" ixy="0.0" ixz="0.0" iyy="1.0" iyz="0.0" izz="1.0"/>
      <!--<inertia ixx="0.00030285" ixy="0.00000761" ixz="0.00000031" iyy="0.00022339" iyz="-0.00000001" izz="0.00039766" />-->
    </inertial>
  </link>
  <!-- Joint 11 -->
  <joint name="joint11" type="revolute">
    <parent link="link11"/>
    <child link="link12"/>
    <origin rpy="0 0 0" xyz="0.06300 0.04500 0.00000"/>
    <axis xyz="0 1 0"/>
    <limit effort="1000" lower="-1.570796327" upper="1.570796327" velocity="6.5"/>
    <dynamics damping="80"/>
  </joint>
  <transmission name="tran11">
    <type>transmission_interface/SimpleTransmission</type>
    <joint name="joint11">
      <hardwareInterface>EffortJointInterface</hardwareInterface>
    </joint>
    <actuator name="motor11">
      <hardwareInterface>EffortJointInterface</hardwareInterface>
      <mechanicalReduction>1</mechanicalReduction>
    </actuator>
  </transmission>
  <!-- link 12 -->
  <link name="link12">
    <collision>
      <origin rpy="0 0 0" xyz="0 0 0"/>
      <geometry>
        <mesh filename="package://rat20_movil/meshes/link_6.stl" scale="0.001 0.001 0.001"/>
      </geometry>
    </collision>
    <visual>
      <origin rpy="0 0 0" xyz="0 0 0"/>
      <geometry>
        <mesh filename="package://rat20_movil/meshes/link_6.stl" scale="0.001 0.001 0.001"/>
      </geometry>
      <material name="grey"/>
    </visual>
    <inertial>
      <origin rpy="0 0 0" xyz="0.06831 -0.04457 0.00000"/>
      <!--<origin xyz="-0.05469 0.00043 0.00000" rpy="0 0 0"/>-->
      <mass value="0.43273"/>
      <inertia ixx="1.0" ixy="0.0" ixz="0.0" iyy="1.0" iyz="0.0" izz="1.0"/>
      <!--<inertia ixx="0.00021512" ixy="0.00001009" ixz="0.00000000" iyy="0.00042827" iyz="0.00000000" izz="0.00051436" />-->
    </inertial>
  </link>
  <!-- Joint 12 -->
  <joint name="joint12" type="revolute">
    <parent link="link12"/>
    <child link="end_link1"/>
    <origin rpy="0 0 0" xyz="0.12300 -0.04500 0.00000"/>
    <axis xyz="1 0 0"/>
    <limit effort="1000" lower="-1.570796327" upper="1.570796327" velocity="6.5"/>
    <dynamics damping="80"/>
  </joint>
  <transmission name="tran12">
    <type>transmission_interface/SimpleTransmission</type>
    <joint name="joint12">
      <hardwareInterface>EffortJointInterface</hardwareInterface>
    </joint>
    <actuator name="motor12">
      <hardwareInterface>EffortJointInterface</hardwareInterface>
      <mechanicalReduction>1</mechanicalReduction>
    </actuator>
  </transmission>
  <!-- end link1 -->
  <link name="end_link1">
    <collision>
      <origin rpy="0 0 0" xyz="0 0 0"/>
      <geometry>
        <mesh filename="package://rat20_movil/meshes/end_link.stl" scale="0.001 0.001 0.001"/>
      </geometry>
    </collision>
    <visual>
      <origin rpy="0 0 0" xyz="0 0 0"/>
      <geometry>
        <mesh filename="package://rat20_movil/meshes/end_link.stl" scale="0.001 0.001 0.001"/>
      </geometry>
      <material name="grey"/>
    </visual>
    <inertial>
      <origin rpy="0 0 0" xyz="0.00337 0.00000 0.00000"/>
      <mass value="0.01919"/>
      <inertia ixx="1.0" ixy="0.0" ixz="0.0" iyy="1.0" iyz="0.0" izz="1.0"/>
      <!--<inertia ixx="0.00000938" ixy="0.0" ixz="0.0" iyy="0.00000338" iyz="0.0" izz="0.00000635" />-->
    </inertial>
  </link>
  <joint name="joint15" type="fixed">
    <origin rpy="-1.57 0 -1.57" xyz="0 0 0"/>
    <parent link="end_link1"/>
    <child link="rh_p12_rn_base_izq"/>
  </joint>
  <!-- base -->
  <link name="rh_p12_rn_base_izq">
    <collision>
      <origin rpy="0 0 0" xyz="0 0 0"/>
      <geometry>
        <mesh filename="package://rat20_movil/meshes/base.stl" scale="0.001 0.001 0.001"/>
      </geometry>
    </collision>
    <visual>
      <origin rpy="0 0 0" xyz="0 0 0"/>
      <geometry>
        <mesh filename="package://rat20_movil/meshes/base.stl" scale="0.001 0.001 0.001"/>
      </geometry>
      <material name="grey"/>
    </visual>
    <inertial>
      <origin rpy="0 0 0" xyz="0.000 0.000 0.032"/>
      <mass value="0.236"/>
      <!--<inertia ixx="0.00017" ixy="0.0" ixz="0.0" iyy="0.00011" iyz="0.0" izz="0.00017" />-->
      <inertia ixx="1.0" ixy="0.0" ixz="0.0" iyy="1.0" iyz="0.0" izz="1.0"/>
    </inertial>
  </link>
  <!-- Joint -->
  <joint name="rh_p12_rn_izq" type="revolute">
    <parent link="rh_p12_rn_base_izq"/>
    <child link="rh_p12_rn_r1_izq"/>
    <origin rpy="0 0 0" xyz="0.0 0.008 0.048"/>
    <axis xyz="1 0 0"/>
    <limit effort="1000" lower="0.0" upper="1.1" velocity="6.5"/>
    <dynamics damping="0.7"/>
  </joint>
  <transmission name="tran_r1_izq">
    <type>transmission_interface/SimpleTransmission</type>
    <joint name="rh_p12_rn_izq">
      <hardwareInterface>hardware_interface/EffortJointInterface</hardwareInterface>
    </joint>
    <actuator name="motor_r1_izq">
      <hardwareInterface>hardware_interface/EffortJointInterface</hardwareInterface>
      <mechanicalReduction>1</mechanicalReduction>
    </actuator>
  </transmission>
  <!-- rh_p12_rn_r1 -->
  <link name="rh_p12_rn_r1_izq">
    <collision>
      <origin rpy="0 0 0" xyz="0 0 0"/>
      <geometry>
        <mesh filename="package://rat20_movil/meshes/r1.stl" scale="0.001 0.001 0.001"/>
      </geometry>
    </collision>
    <visual>
      <origin rpy="0 0 0" xyz="0 0 0"/>
      <geometry>
        <mesh filename="package://rat20_movil/meshes/r1.stl" scale="0.001 0.001 0.001"/>
      </geometry>
      <material name="grey"/>
    </visual>
    <inertial>
      <origin rpy="0 0 0" xyz="0.000 0.034 0.004"/>
      <mass value="0.068"/>
      <!--<inertia ixx="0.00004" ixy="0.0" ixz="0.0" iyy="0.00002" iyz="-0.00001" izz="0.00002" />-->
      <inertia ixx="1.0" ixy="0.0" ixz="0.0" iyy="1.0" iyz="0.0" izz="1.0"/>
    </inertial>
  </link>
  <!-- Right Joint 2 -->
  <joint name="rh_r2_izq" type="revolute">
    <parent link="rh_p12_rn_r1_izq"/>
    <child link="rh_p12_rn_r2_izq"/>
    <origin rpy="0 0 0" xyz="0.0 0.0493634 0.0285"/>
    <axis xyz="-1 0 0"/>
    <limit effort="1000" lower="0.0" upper="1.0" velocity="6.5"/>
    <dynamics damping="0.7"/>
  </joint>
  <transmission name="tran_r2_izq">
    <type>transmission_interface/SimpleTransmission</type>
    <joint name="rh_r2_izq">
      <hardwareInterface>hardware_interface/EffortJointInterface</hardwareInterface>
    </joint>
    <actuator name="motor_r2_izq">
      <hardwareInterface>hardware_interface/EffortJointInterface</hardwareInterface>
      <mechanicalReduction>1</mechanicalReduction>
    </actuator>
  </transmission>
  <!-- rh_p12_rn_r2 -->
  <link name="rh_p12_rn_r2_izq">
    <collision>
      <origin rpy="0 0 0" xyz="0 0 0"/>
      <geometry>
        <mesh filename="package://rat20_movil/meshes/r2.stl" scale="0.001 0.001 0.001"/>
      </geometry>
    </collision>
    <visual>
      <origin rpy="0 0 0" xyz="0 0 0"/>
      <geometry>
        <mesh filename="package://rat20_movil/meshes/r2.stl" scale="0.001 0.001 0.001"/>
      </geometry>
      <material name="grey"/>
    </visual>
    <inertial>
      <origin rpy="0 0 0" xyz="0.000 0.006 0.011"/>
      <mass value="0.022"/>
      <!--<inertia ixx="0.0" ixy="0.0" ixz="0.0" iyy="0.00001" iyz="0.0" izz="0.0" />-->
      <inertia ixx="1.0" ixy="0.0" ixz="0.0" iyy="1.0" iyz="0.0" izz="1.0"/>
    </inertial>
  </link>
  <!-- Left Joint 1 -->
  <joint name="rh_l1_izq" type="revolute">
    <parent link="rh_p12_rn_base_izq"/>
    <child link="rh_p12_rn_l1_izq"/>
    <origin rpy="0 0 0" xyz="0.0 -0.008 0.048"/>
    <axis xyz="-1 0 0"/>
    <limit effort="1000" lower="0.0" upper="1.1" velocity="6.5"/>
    <dynamics damping="0.7"/>
  </joint>
  <transmission name="tran_l1_izq">
    <type>transmission_interface/SimpleTransmission</type>
    <joint name="rh_l1_izq">
      <hardwareInterface>hardware_interface/EffortJointInterface</hardwareInterface>
    </joint>
    <actuator name="motor_l1_izq">
      <hardwareInterface>hardware_interface/EffortJointInterface</hardwareInterface>
      <mechanicalReduction>1</mechanicalReduction>
    </actuator>
  </transmission>
  <!-- rh_p12_rn_l1 -->
  <link name="rh_p12_rn_l1_izq">
    <collision>
      <origin rpy="0 0 0" xyz="0 0 0"/>
      <geometry>
        <mesh filename="package://rat20_movil/meshes/l1.stl" scale="0.001 0.001 0.001"/>
      </geometry>
    </collision>
    <visual>
      <origin rpy="0 0 0" xyz="0 0 0"/>
      <geometry>
        <mesh filename="package://rat20_movil/meshes/l1.stl" scale="0.001 0.001 0.001"/>
      </geometry>
      <material name="grey"/>
    </visual>
    <inertial>
      <origin rpy="0 0 0" xyz="0.000 -0.034 0.004"/>
      <mass value="0.068"/>
      <!--<inertia ixx="0.00004" ixy="0.0" ixz="0.0" iyy="0.00002" iyz="0.00001" izz="0.00002" />-->
      <inertia ixx="1.0" ixy="0.0" ixz="0.0" iyy="1.0" iyz="0.0" izz="1.0"/>
    </inertial>
  </link>
  <!-- Left Joint 2 -->
  <joint name="rh_l2_izq" type="revolute">
    <parent link="rh_p12_rn_l1_izq"/>
    <child link="rh_p12_rn_l2_izq"/>
    <origin rpy="0 0 0" xyz="0.0 -0.0493634 0.0285"/>
    <axis xyz="1 0 0"/>
    <limit effort="1000" lower="0.0" upper="1.0" velocity="6.5"/>
    <dynamics damping="0.7"/>
  </joint>
  <transmission name="tran_l2_izq">
    <type>transmission_interface/SimpleTransmission</type>
    <joint name="rh_l2_izq">
      <hardwareInterface>hardware_interface/EffortJointInterface</hardwareInterface>
    </joint>
    <actuator name="motor_l2_izq">
      <hardwareInterface>hardware_interface/EffortJointInterface</hardwareInterface>
      <mechanicalReduction>1</mechanicalReduction>
    </actuator>
  </transmission>
  <!-- rh_p12_rn_l2 -->
  <link name="rh_p12_rn_l2_izq">
    <collision>
      <origin rpy="0 0 0" xyz="0 0 0"/>
      <geometry>
        <mesh filename="package://rat20_movil/meshes/l2.stl" scale="0.001 0.001 0.001"/>
      </geometry>
    </collision>
    <visual>
      <origin rpy="0 0 0" xyz="0 0 0"/>
      <geometry>
        <mesh filename="package://rat20_movil/meshes/l2.stl" scale="0.001 0.001 0.001"/>
      </geometry>
      <material name="grey"/>
    </visual>
    <inertial>
      <origin rpy="0 0 0" xyz="0.000 -0.006 0.011"/>
      <mass value="0.022"/>
      <!--<inertia ixx="0.0" ixy="0.0" ixz="0.0" iyy="0.00001" iyz="0.0" izz="0.0" />-->
      <inertia ixx="1.0" ixy="0.0" ixz="0.0" iyy="1.0" iyz="0.0" izz="1.0"/>
    </inertial>
  </link>
  <joint name="world_fixed4" type="continuous">
    <origin rpy="1.57 -3.14 0" xyz="0 0 0.3"/>
    <parent link="world"/>
    <child link="chasis"/>
  </joint>
  <!-- PARTE DEL CHASIS -->
  <link name="chasis">
    <inertial>
      <origin rpy="0 0 0" xyz="0.19826 0.00059528 -0.093428"/>
      <mass value="30.428"/>
      <inertia ixx="0.14317" ixy="0.0012711" ixz="-0.015594" iyy="0.40158" iyz="8.4926E-06" izz="0.40545"/>
    </inertial>
    <visual>
      <origin rpy="0 0 0" xyz="0 0 0"/>
      <geometry>
        <mesh filename="package://rat20_movil/meshes/chasis.STL" scale="1 1 1"/>
      </geometry>
      <material name="grey"/>
    </visual>
    <collision>
      <origin rpy="0 0 0" xyz="0 0 0"/>
      <geometry>
        <mesh filename="package://rat20_movil/meshes/chasis.STL" scale="1 1 1"/>
      </geometry>
    </collision>
  </link>

  <!-- PARTE DE LA RUEDA NUMERO 1: izquierda frontal -->
  <link name="rueda1">
    <inertial>
      <origin rpy="0 0 0" xyz="1.898E-06 -9.4096E-07 -0.10103"/>
      <mass value="2.2464"/>
      <inertia ixx="0.0080453" ixy="-7.611E-08" ixz="8.2614E-08" iyy="0.0080454" iyz="1.8052E-07" izz="0.011889"/>
    </inertial>
    <visual>
      <origin rpy="0 0 0" xyz="0 0 0"/>
      <geometry>
        <mesh filename="package://rat20_movil/meshes/rueda1.STL" scale="1 1 1"/>
      </geometry>
      <material name="grey"/>
    </visual>
    <collision>
      <origin rpy="0 0 0" xyz="0 0 0"/>
      <geometry>
        <mesh filename="package://rat20_movil/meshes/rueda1.STL" scale="1 1 1"/>
      </geometry>
    </collision>
  </link>
  <joint name="ejeIzqF" type="continuous">
    <origin rpy="0 0 -1.2858" xyz="-0.054 0.1548 -0.1651"/>
    <parent link="chasis"/>
    <child link="rueda1"/>
    <axis xyz="0 0 1"/>
    <!-- <limit velocity="6.5" effort="1000"/> -->
    <dynamics damping="10.7" friction="0.0"/>
  </joint>
  <transmission name="tran1_izq">
    <type>transmission_interface/SimpleTransmission</type>
    <joint name="ejeIzqF">
      <hardwareInterface>EffortJointInterface</hardwareInterface>
    </joint>
    <actuator name="motor1_izq">
      <hardwareInterface>EffortJointInterface</hardwareInterface>
      <mechanicalReduction>1</mechanicalReduction>
    </actuator>
  </transmission>

  <!-- PARTE DE LA RUEDA 2: derecha frontal -->
  <link name="rueda2">
    <inertial>
      <origin rpy="0 0 0" xyz="1.9419E-06 -9.407E-07 -0.10103"/>
      <mass value="2.2464"/>
      <inertia ixx="0.0080453" ixy="-7.6009E-08" ixz="8.3318E-08" iyy="0.0080454" iyz="1.8056E-07" izz="0.011889"/>
    </inertial>
    <visual>
      <origin rpy="0 0 0" xyz="0 0 0"/>
      <geometry>
        <mesh filename="package://rat20_movil/meshes/rueda1.STL" scale="1 1 1"/>
      </geometry>
      <material name="grey"/>
    </visual>
    <collision>
      <origin rpy="0 0 0" xyz="0 0 0"/>
      <geometry>
        <mesh filename="package://rat20_movil/meshes/rueda1.STL" scale="1 1 1"/>
      </geometry>
    </collision>
  </link>
  <joint name="ejeDerF" type="continuous">
    <origin rpy="3.1416 0 -2.609" xyz="-0.054 0.1548 0.1651"/>
    <parent link="chasis"/>
    <child link="rueda2"/>
    <axis xyz="0 0 1"/>
    <!-- <limit velocity="6.5" effort="1000"/> -->
    <dynamics damping="10.7" friction="0.0"/>
  </joint>
  <transmission name="tran2_der">
    <type>transmission_interface/SimpleTransmission</type>
    <joint name="ejeDerF">
      <hardwareInterface>EffortJointInterface</hardwareInterface>
    </joint>
    <actuator name="motor2_der">
      <hardwareInterface>EffortJointInterface</hardwareInterface>
      <mechanicalReduction>1</mechanicalReduction>
    </actuator>
  </transmission>

  <!-- PARTE DE LA RUEDA 3: izquierda trasera-->
  <link name="rueda3">
    <inertial>
      <origin rpy="0 0 0" xyz="1.8552E-06 -9.4048E-07 -0.10103"/>
      <mass value="2.2464"/>
      <inertia ixx="0.0080453" ixy="-7.6081E-08" ixz="8.1449E-08" iyy="0.0080454" iyz="1.8052E-07" izz="0.011889"/>
    </inertial>
    <visual>
      <origin rpy="0 0 0" xyz="0 0 0"/>
      <geometry>
        <mesh filename="package://rat20_movil/meshes/rueda1.STL" scale="1 1 1"/>
      </geometry>
      <material name="grey"/>
    </visual>
    <collision>
      <origin rpy="0 0 0" xyz="0 0 0"/>
      <geometry>
        <mesh filename="package://rat20_movil/meshes/rueda1.STL" scale="1 1 1"/>
      </geometry>
    </collision>
  </link>
  <joint name="ejeIzqT" type="continuous">
    <origin rpy="0 0 -1.379" xyz="0.446 0.1548 -0.1651"/>
    <parent link="chasis"/>
    <child link="rueda3"/>
    <axis xyz="0 0 1"/>
    <!-- <limit velocity="6.5" effort="1000"/> -->
    <dynamics damping="10.7" friction="0.0"/>
  </joint>
  <transmission name="tran3_izq">
    <type>transmission_interface/SimpleTransmission</type>
    <joint name="ejeIzqT">
      <hardwareInterface>EffortJointInterface</hardwareInterface>
    </joint>
    <actuator name="motor3_izq">
      <hardwareInterface>EffortJointInterface</hardwareInterface>
      <mechanicalReduction>1</mechanicalReduction>
    </actuator>
  </transmission>

  <!-- PARTE DE LA RUEDA 4: derecha trasera-->
  <link name="rueda4">
    <inertial>
      <origin rpy="0 0 0" xyz="1.8724E-06 -9.41E-07 -0.10103"/>
      <mass value="2.2464"/>
      <inertia ixx="0.0080453" ixy="-7.6089E-08" ixz="7.9894E-08" iyy="0.0080453" iyz="1.8053E-07" izz="0.011889"/>
    </inertial>
    <visual>
      <origin rpy="0 0 0" xyz="0 0 0"/>
      <geometry>
        <mesh filename="package://rat20_movil/meshes/rueda1.STL" scale="1 1 1"/>
      </geometry>
      <material name="grey"/>
    </visual>
    <collision>
      <origin rpy="0 0 0" xyz="0 0 0"/>
      <geometry>
        <mesh filename="package://rat20_movil/meshes/rueda1.STL" scale="1 1 1"/>
      </geometry>
    </collision>
  </link>
  <joint name="ejeDerT" type="continuous">
    <origin rpy="3.1416 0 -2.6599" xyz="0.446 0.1548 0.1651"/>
    <parent link="chasis"/>
    <child link="rueda4"/>
    <axis xyz="0 0 1"/>
    <!-- <limit velocity="6.5" effort="1000"/> -->
    <dynamics damping="10.7" friction="0.0"/>
  </joint>
  <transmission name="tran4_der">
    <type>transmission_interface/SimpleTransmission</type>
    <joint name="ejeDerT">
      <hardwareInterface>EffortJointInterface</hardwareInterface>
    </joint>
    <actuator name="motor4_der">
      <hardwareInterface>EffortJointInterface</hardwareInterface>
      <mechanicalReduction>1</mechanicalReduction>
    </actuator>
  </transmission>
  <!-- PARTE DE LA BASE -->
  <link name="base1">
    <inertial>
      <origin rpy="0 0 0" xyz="-0.0006365 0.00063671 0.042268"/>
      <mass value="4.5655"/>
      <inertia ixx="0.010577" ixy="4.9602E-05" ixz="-0.00016934" iyy="0.0094434" iyz="4.9221E-06" izz="0.013211"/>
    </inertial>
    <visual>
      <origin rpy="0 0 0" xyz="0 0 0"/>
      <geometry>
        <mesh filename="package://rat20_movil/meshes/base1.stl" scale="1 1 1"/>
      </geometry>
      <material name="grey"/>
    </visual>
    <collision>
      <origin rpy="0 0 0" xyz="0 0 0"/>
      <geometry>
        <mesh filename="package://rat20_movil/meshes/base1.stl" scale="1 1 1"/>
      </geometry>
    </collision>
  </link>
  <joint name="ejeBase" type="continuous">
    <origin rpy="1.5708 -0.02106 0" xyz="0 0 0"/>
    <parent link="chasis"/>
    <child link="base1"/>
    <axis xyz="0 0 1"/>
    <dynamics damping="10.7" friction="0.0"/>
  </joint>

  <transmission name="tranBase">
    <type>transmission_interface/SimpleTransmission</type>
    <joint name="ejeBase">
      <hardwareInterface>EffortJointInterface</hardwareInterface>
    </joint>
    <actuator name="motorBase">
      <hardwareInterface>EffortJointInterface</hardwareInterface>
      <mechanicalReduction>1</mechanicalReduction>
    </actuator>
  </transmission>
  <link name="torso">
    <inertial>
      <origin rpy="0 0 0" xyz="0.00035431 0.13814 -0.0042036"/>
      <mass value="3.984"/>
      <inertia ixx="0.0056895" ixy="-3.5752E-05" ixz="-1.1581E-05" iyy="0.0056032" iyz="3.2469E-05" izz="0.0097762"/>
    </inertial>
    <visual>
      <origin rpy="0 0 0" xyz="0 0 0"/>
      <geometry>
        <mesh filename="package://rat20_movil/meshes/torso.STL"/>
      </geometry>
      <material name="grey"/>
    </visual>
    <collision>
      <origin rpy="0 0 0" xyz="0 0 0"/>
      <geometry>
        <mesh filename="package://rat20_movil/meshes/torso.STL"/>
      </geometry>
    </collision>
  </link>
  <joint name="eje6" type="continuous">
    <origin rpy="1.5708 0 -1.5708" xyz="-0.07 0 0.078"/>
    <parent link="base1"/>
    <child link="torso"/>
    <axis xyz="1 0 0"/>
  </joint>
  <link name="perno">
    <inertial>
      <origin rpy="0 0 0" xyz="-1.4792E-16 -6.9389E-18 0"/>
      <mass value="0.008093"/>
      <inertia ixx="3.5986E-08" ixy="-1.2458E-22" ixz="3.3179E-23" iyy="9.2017E-07" iyz="3.2452E-24" izz="9.2017E-07"/>
    </inertial>
    <visual>
      <origin rpy="0 0 0" xyz="0 0 0"/>
      <geometry>
        <mesh filename="package://rat20_movil/meshes/perno.STL"/>
      </geometry>
      <material name="grey"/>
    </visual>
    <collision>
      <origin rpy="0 0 0" xyz="0 0 0"/>
      <geometry>
        <mesh filename="package://rat20_movil/meshes/perno.STL"/>
      </geometry>
    </collision>
  </link>
<joint name="eje7" type="continuous">
    <origin rpy="1.5708 0 0" xyz="0 0.184 -0.105"/>
    <parent link="torso"/>
    <child link="perno"/>
    <axis xyz="1 0 0"/>
  </joint> 
<link
    name="motor_lineal">
    <inertial>
      <origin
        xyz="-4.7858E-09 0.015206 0.083953"
        rpy="0 0 0" />
      <mass
        value="0.97646" />
      <inertia
        ixx="0.0033834"
        ixy="-1.4738E-10"
        ixz="-2.9767E-10"
        iyy="0.0030359"
        iyz="0.00020997"
        izz="0.00053991" />
    </inertial>
    <visual>
      <origin
        xyz="0 0 0"
        rpy="0 0 0" />
      <geometry>
        <mesh
          filename="package://rat20_movil/meshes/motor_lineal.STL" />
      </geometry>
      <material
        name="">
        <color
          rgba="0.90196 0.92157 0.92157 1" />
      </material>
    </visual>
    <collision>
      <origin
        xyz="0 0 0"
        rpy="0 0 0" />
      <geometry>
        <mesh
          filename="package://rat20_movil/meshes/motor_lineal.STL" />
      </geometry>
    </collision>
  </link>
  <joint
    name="eje8"
    type="continuous">
    <origin
      xyz="0.104 0 0.03"
      rpy="0.28908 0 -1.5708" />
    <parent
      link="base1" />
    <child
      link="motor_lineal" />
    <axis
      xyz="1 0 0" />
  </joint>
<gazebo>
  <plugin name="Myrobot_ClosedLoopPlugin"       filename="libpegasus_gazebo_closed_loop_plugin.so">
    <joint>eje8</joint> 
   <child>motor_lineal</child> 
    <parent>base1</parent>
    <position>0.104 0 0.03</position>
    <rotation>0.28908 0 -1.5708</rotation>
  </plugin>
</gazebo>
<link
    name="accion_lineal">
    <inertial>
      <origin
        xyz="4.9324E-09 2.2185E-09 0.076684"
        rpy="0 0 0" />
      <mass
        value="0.14682" />
      <inertia
        ixx="0.00041695"
        ixy="6.3911E-13"
        ixz="-5.0141E-11"
        iyy="0.00041691"
        iyz="-2.1245E-11"
        izz="6.6825E-06" />
    </inertial>
    <visual>
      <origin
        xyz="0 0 0"
        rpy="0 0 0" />
      <geometry>
        <mesh
          filename="package://rat20_movil/meshes/accion_lineal.STL" />
      </geometry>
      <material
        name="">
        <color
          rgba="0.90196 0.92157 0.92157 1" />
      </material>
    </visual>
    <collision>
      <origin
        xyz="0 0 0"
        rpy="0 0 0" />
      <geometry>
        <mesh
          filename="package://rat20_movil/meshes/accion_lineal.STL" />
      </geometry>
    </collision>
  </link>
  <joint
    name="eje9"
    type="continuous">
    <origin
      xyz="0 0 0.081496"
      rpy="0 0 0" />
    <parent
      link="motor_lineal" />
    <child
      link="accion_lineal" />
    <axis
      xyz="0 0 1" />
  </joint>
   <joint name="eje50" type="continuous">
    <origin rpy="1.5708 0 0" xyz="0 0 0.16"/>
    <parent link="accion_lineal"/>
    <child link="perno"/>
    <axis xyz="1 0 0"/>
    </joint> 
    <gazebo>
      <plugin name="Myrobot_ClosedLoopPlugin"       filename="libpegasus_gazebo_closed_loop_plugin.so">
        <joint>eje7</joint> 
        <parent link="torso"/>
        <child link="perno"/>
      </plugin>
    </gazebo>
</robot>
