<?xml version="1.0" encoding="utf-8"?>
<!-- This URDF was automatically created by SolidWorks to URDF Exporter! Originally created by Stephen Brawner (brawner@gmail.com) 
     Commit Version: 1.6.0-1-g15f4949  Build Version: 1.6.7594.29634
     For more information, please see http://wiki.ros.org/sw_urdf_exporter -->
<robot
  name="mmdt_rat20">

<!-- PAGINA PARA VER LAS FRICCIONES: -->
<!-- https://www.engineeringtoolbox.com/friction-coefficients-d_778.html -->

	<!-- <link name="world">
	</link> -->

	<!-- <joint name="world_fixed" type="continuous">
		<origin xyz="0 0 0.3" rpy="-1.57 0 0"/>
		<parent link="world"/>
		<child link="chasis"/>
	</joint> -->

<!-- PARTE DEL CHASIS -->
	<link
    name="chasis">
    <inertial>
      <origin
        xyz="0.19826 0.00059528 -0.093428"
		    rpy="0 0 0" />
		<mass
        value="30.428" /> <!-- Valor original: 30.428-->
      <inertia
        ixx="0.14317"
        ixy="0.0012711"
        ixz="-0.015594"
        iyy="0.40158"
        iyz="8.4926E-06"
        izz="0.40545" />
    </inertial>
    <visual>
      <origin
        xyz="0 0 0"
        rpy="0 0 0" />
      <geometry>
        <mesh
          filename="package://mmdt_rat20/meshes/chasis.STL" />
          <!-- <box size="0.6 0.1 0.2"/> -->
      </geometry>
      <material
        name="">
        <color
          rgba="0.75294 0.75294 0.75294 1" />
      </material>
    </visual>
    <collision>
      <origin
        xyz="0 0 0"
        rpy="0 0 0" />
      <geometry>
        <mesh
          filename="package://mmdt_rat20/meshes/chasis.STL" />
        <!-- <box size="0.6 0.1 0.4"/> -->
      </geometry>

      <surface>
            <friction>
              <ode>
                <mu>1.000000</mu>
                <mu2>1.000000</mu2>
                <fdir1>0.0 0.0 0.0</fdir1>
                <slip1>0.000000</slip1>
                <slip2>0.000000</slip2>
              </ode>
            </friction>
      </surface>

    </collision>
  </link>


<!-- PARTE DE LA RUEDA NUMERO 1: izquierda frontal -->

  <link
    name="rueda1">
    <inertial>
      <origin
        xyz="1.898E-06 -9.4096E-07 -0.10103"
        rpy="0 0 0" />
      <mass
        value="2.2464" />
      <inertia
        ixx="0.0080453"
        ixy="-7.611E-08"
        ixz="8.2614E-08"
        iyy="0.0080454"
        iyz="1.8052E-07"
        izz="0.011889" />
    </inertial>
    <visual>
      <origin
        xyz="0 0 0"
        rpy="0 0 0" />
      <geometry>
        <mesh
          filename="package://mmdt_rat20/meshes/rueda1.STL" />
        <!-- <cylinder length="0.05" radius="0.13"/> -->
      </geometry>
      <material
        name="">
        <color
          rgba="0 0.75294 0.75294 1" />
      </material>
    </visual>
    <collision>

    <!-- <origin
        xyz="0 0 0"
        rpy="0 0 0" /> -->
        <!-- ESTO ERA LO ORIGINAL PERO HE MOVIDO LA COLISION PARA QUE NO CHOQUE CON EL CHASIS -->  

      <origin
        xyz="0 0 -0.1"
        rpy="0 0 0" />
      <geometry>
        <!-- <mesh
          filename="package://rat20_movil/meshes/rueda1.STL" /> -->
        <cylinder length="0.03" radius="0.13"/>
      </geometry>
      

    </collision>
  </link>
  <joint
    name="aEjeRuedaIzqF"
    type="continuous">

    <origin
      xyz="-0.054 0.1548 -0.1651"
      rpy="0 0 -1.2858" />

    <parent
      link="chasis" />
    <child
      link="rueda1" />
    <axis
      xyz="0 0 1" />
    <!-- <limit velocity="6.5" effort="1000"/> -->
    <dynamics damping="20" friction="20"/>
  </joint>

  <transmission name="tran1">
    <type>transmission_interface/SimpleTransmission</type>
    <joint name="aEjeRuedaIzqF">
      <hardwareInterface>EffortJointInterface</hardwareInterface>
    </joint>
    <actuator name="motor1">
      <hardwareInterface>EffortJointInterface</hardwareInterface>
      <mechanicalReduction>1</mechanicalReduction>
    </actuator>
  </transmission>

<!-- PARTE DE LA RUEDA 2: derecha frontal -->

  <link
    name="rueda2">
    <inertial>
      <origin
        xyz="1.9419E-06 -9.407E-07 -0.10103"
        rpy="0 0 0" />
      <mass
        value="2.2464" />
      <inertia
        ixx="0.0080453"
        ixy="-7.6009E-08"
        ixz="8.3318E-08"
        iyy="0.0080454"
        iyz="1.8056E-07"
        izz="0.011889" />
    </inertial>
    <visual>
      <origin
        xyz="0 0 0"
        rpy="0 0 0" />
      <geometry>
        <mesh
          filename="package://mmdt_rat20/meshes/rueda1.STL" />
        <!-- <cylinder length="0.05" radius="0.13"/> -->
      </geometry>
      <material
        name="">
        <color
          rgba="0.75294 0.75294 0.75294 1" />
      </material>
    </visual>
    <collision>

    <!-- <origin
        xyz="0 0 0"
        rpy="0 0 0" /> -->
        <!-- ESTO ERA LO ORIGINAL PERO HE MOVIDO LA COLISION PARA QUE NO CHOQUE CON EL CHASIS -->

      <origin
        xyz="0 0 -0.1"
        rpy="0 0 0" />
      <geometry>
        <!-- <mesh
          filename="package://rat20_movil/meshes/rueda1.STL" /> -->
        <cylinder length="0.03" radius="0.13"/>
      </geometry>


    </collision>
  </link>
  <joint
    name="aEjeRuedaDerF"
    type="continuous">

    <origin
      xyz="-0.054 0.1548 0.1651" 
      rpy="3.1416 0 -2.609" /> 

    <parent
      link="chasis" />
    <child
      link="rueda2" />
    <axis
      xyz="0 0 1" />
    <!-- <limit velocity="6.5" effort="1000"/> -->
    <dynamics damping="20" friction="20"/>
  </joint>

  <transmission name="tran2">
    <type>transmission_interface/SimpleTransmission</type>
    <joint name="aEjeRuedaDerF">
      <hardwareInterface>EffortJointInterface</hardwareInterface>
    </joint>
    <actuator name="motor2">
      <hardwareInterface>EffortJointInterface</hardwareInterface>
      <mechanicalReduction>1</mechanicalReduction>
    </actuator>
  </transmission>

  <!-- PARTE DE LA RUEDA 3: izquierda trasera-->
  <link
    name="rueda3">
    <inertial>
      <origin
        xyz="1.8552E-06 -9.4048E-07 -0.10103"
        rpy="0 0 0" />
      <mass
        value="2.2464" />
      <inertia
        ixx="0.0080453"
        ixy="-7.6081E-08"
        ixz="8.1449E-08"
        iyy="0.0080454"
        iyz="1.8052E-07"
        izz="0.011889" />
    </inertial>
    <visual>
      <origin
        xyz="0 0 0"
        rpy="0 0 0" />
      <geometry>
        <mesh
          filename="package://mmdt_rat20/meshes/rueda1.STL" />
        <!-- <cylinder length="0.05" radius="0.13"/> -->
      </geometry>
      <material
        name="">
        <color
          rgba="0.75294 0.75294 0.75294 1" />
      </material>
    </visual>
    <collision>

    <!-- <origin
        xyz="0 0 0"
        rpy="0 0 0" /> -->
        <!-- ESTO ERA LO ORIGINAL PERO HE MOVIDO LA COLISION PARA QUE NO CHOQUE CON EL CHASIS -->

      <origin
        xyz="0 0 -0.1"
        rpy="0 0 0" />
      <geometry>
        <!-- <mesh
          filename="package://rat20_movil/meshes/rueda1.STL" /> -->
        <cylinder length="0.03" radius="0.13"/>
      </geometry>


    </collision>
  </link>
  <joint
    name="aEjeRuedaIzqT"
    type="continuous">

    <origin
      xyz="0.446 0.1548 -0.1651"
      rpy="0 0 -1.379" />

    <parent
      link="chasis" />
    <child
      link="rueda3" />
    <axis
      xyz="0 0 1" />
    <!-- <limit velocity="6.5" effort="1000"/> -->
    <dynamics damping="20" friction="20"/>
  </joint>
  

  <transmission name="tran3">
    <type>transmission_interface/SimpleTransmission</type>
    <joint name="aEjeRuedaIzqT">
      <hardwareInterface>EffortJointInterface</hardwareInterface>
    </joint>
    <actuator name="motor3">
      <hardwareInterface>EffortJointInterface</hardwareInterface>
      <mechanicalReduction>1</mechanicalReduction>
    </actuator>
  </transmission>

  <!-- PARTE DE LA RUEDA 4: derecha trasera-->
  <link
    name="rueda4">
    <inertial>
      <origin
        xyz="1.8724E-06 -9.41E-07 -0.10103"
        rpy="0 0 0" />
      <mass
        value="2.2464" />
      <inertia
        ixx="0.0080453"
        ixy="-7.6089E-08"
        ixz="7.9894E-08"
        iyy="0.0080453"
        iyz="1.8053E-07"
        izz="0.011889" />
    </inertial>
    <visual>
      <origin
        xyz="0 0 0"
        rpy="0 0 0" />
      <geometry>
        <mesh
          filename="package://mmdt_rat20/meshes/rueda1.STL" />
        <!-- <cylinder length="0.05" radius="0.13"/> -->
      </geometry>
      <material
        name="">
        <color
          rgba="0.75294 0.75294 0.75294 1" />
      </material>
    </visual>
    <collision>

    <!-- <origin
        xyz="0 0 0"
        rpy="0 0 0" /> -->
        <!-- ESTO ERA LO ORIGINAL PERO HE MOVIDO LA COLISION PARA QUE NO CHOQUE CON EL CHASIS -->

      <origin
        xyz="0 0 -0.1"
        rpy="0 0 0" />
      <geometry>
        <!-- <mesh
          filename="package://rat20_movil/meshes/rueda1.STL" /> -->
        <cylinder length="0.03" radius="0.13"/>
      </geometry>

    </collision>
  </link>

  <joint
    name="aEjeRuedaDerT"
    type="continuous">
    <origin
      xyz="0.446 0.1548 0.1651"
      rpy="3.1416 0 -2.6599" />
    <parent
      link="chasis" />
    <child
      link="rueda4" />
    <axis
      xyz="0 0 1" />
    <!-- <limit velocity="6.5" effort="1000"/> -->
    <dynamics damping="20" friction="20"/>
  </joint>

  <transmission name="tran4">
    <type>transmission_interface/SimpleTransmission</type>
    <joint name="aEjeRuedaDerT">
      <hardwareInterface>EffortJointInterface</hardwareInterface>
    </joint>
    <actuator name="motor4">
      <hardwareInterface>EffortJointInterface</hardwareInterface>
      <mechanicalReduction>1</mechanicalReduction>
    </actuator>
  </transmission>


<!-- AJUSTE PARA LA FRICCION CON EL PISO DE TODAS LAS RUEDAS -->
  <gazebo reference="rueda1">
    <kp>1000000.0</kp>
    <!-- kp and kd for rubber -->
    <kd>100.0</kd>
    <mu1>1.0</mu1>
    <!-- was 10 -->
    <mu2>1.0</mu2>
    <maxVel>1.0</maxVel>
    <minDepth>0.00</minDepth>
    <material value="Gazebo/DarkGrey"/>
  </gazebo>

  <gazebo reference="rueda2">
    <kp>1000000.0</kp>
    <!-- kp and kd for rubber -->
    <kd>100.0</kd>
    <mu1>1.0</mu1>
    <!-- was 10 -->
    <mu2>1.0</mu2>
    <maxVel>1.0</maxVel>
    <minDepth>0.00</minDepth>
    <material value="Gazebo/DarkGrey"/>
  </gazebo>

  <gazebo reference="rueda3">
    <kp>1000000.0</kp>
    <!-- kp and kd for rubber -->
    <kd>100.0</kd>
    <mu1>1.0</mu1>
    <!-- was 10 -->
    <mu2>1.0</mu2>
    <maxVel>1.0</maxVel>
    <minDepth>0.00</minDepth>
    <material value="Gazebo/DarkGrey"/>
  </gazebo>

  <gazebo reference="rueda4">
    <kp>1000000.0</kp>
    <!-- kp and kd for rubber -->
    <kd>100.0</kd>
    <mu1>1.0</mu1>
    <!-- was 10 -->
    <mu2>1.0</mu2>
    <maxVel>1.0</maxVel>
    <minDepth>0.00</minDepth>
    <material value="Gazebo/DarkGrey"/>
  </gazebo>

<!-- PARTE DE LA BASE DEL TORSO-->
  <link
    name="baseTorso">
    <inertial>
      <origin
        xyz="-0.0006365 0.00063671 0.042268"
        rpy="0 0 0" />
      <mass
        value="4.5655" />    <!-- Valor original: 4.5655-->
      <inertia
        ixx="0.010577"
        ixy="4.9602E-05"
        ixz="-0.00016934"
        iyy="0.0094434"
        iyz="4.9221E-06"
        izz="0.013211" />
    </inertial>
    <visual>
      <origin
        xyz="0 0 0"
        rpy="0 0 0" />
      <geometry>
        <mesh
          filename="package://mmdt_rat20/meshes/base.STL" />
      </geometry>
      <material
        name="">
        <color
          rgba="0.75294 0.75294 0.75294 1" />
      </material>
    </visual>
    <collision>
      <origin
        xyz="0 0 0"
        rpy="0 0 0" />
      <geometry>
        <mesh
          filename="package://mmdt_rat20/meshes/base.STL" />
      </geometry>
    </collision>
  </link>

  <joint
    name="bEjeBaseTorso"
    type="revolute">
    <origin
      xyz="0 0 0"
      rpy="1.5708 -0.02106 0" />
    <parent
      link="chasis" />
    <child
      link="baseTorso" />
    <axis
      xyz="0 0 1" />
    <!-- <limit velocity="6.5" effort="1000" lower="${-pi*0.5}" upper="${pi*0.5}" /> -->
    <limit velocity="6.5" effort="1000" lower="-0.3" upper="0.3" />
    <dynamics damping="1"/>
  </joint>

  <transmission name="tranBase">
    <type>transmission_interface/SimpleTransmission</type>
    <joint name="bEjeBaseTorso">
      <hardwareInterface>EffortJointInterface</hardwareInterface>
    </joint>
    <actuator name="motorBase">
      <hardwareInterface>EffortJointInterface</hardwareInterface>
      <mechanicalReduction>1</mechanicalReduction>
    </actuator>
  </transmission>


<!-- PARTE DEL TORSO -->
  <link name="torso">
    <inertial>
      <origin rpy="0 0 0" xyz="0.00035431 0.13814 -0.0042036"/>  
      <mass value="3.984"/>
      <inertia ixx="0.0056895" ixy="-3.5752E-05" ixz="-1.1581E-05" iyy="0.0056032" iyz="3.2469E-05" izz="0.0097762"/>
    </inertial>
    <visual>
      <origin rpy="0 0 0" xyz="0 0 0"/>
      <geometry>
        <mesh filename="package://mmdt_rat20/meshes/torso.STL"/>
      </geometry>
      <material name="grey"/>
    </visual>
  </link>
  
  <joint name="bEjeTorso" type="revolute">
    <origin rpy="1.5708 0 -1.5708" xyz="-0.07 0 0.11"/>
    <!-- <origin rpy="1.5708 0 -1.5708" xyz="-0.07 0 0.078"/> -->
    <parent link="baseTorso"/>
    <child link="torso"/>
    <axis xyz="1 0 0"/>
    <!-- <limit velocity="6.5" effort="1000" lower="${-pi}" upper="${pi}" /> -->
    <!-- <limit velocity="6.5" effort="1000" lower="-0.3" upper="0.3" /> -->
    <limit velocity="6.5" effort="1000" lower="0.0" upper="0.3" />
    <dynamics damping="100"/>
  </joint>

  <transmission name="tranBase">
    <type>transmission_interface/SimpleTransmission</type>
    <joint name="bEjeTorso">
      <hardwareInterface>EffortJointInterface</hardwareInterface>
    </joint>
    <actuator name="motorTorso">
      <hardwareInterface>EffortJointInterface</hardwareInterface>
      <mechanicalReduction>1</mechanicalReduction>
    </actuator>
  </transmission>


<!-- *************************** BRAZO DERECHO ***************************** -->
<!-- *********************************************************************** -->

  <joint name="world_fixedDer" type="fixed">
    <origin rpy="0 -1.57 0" xyz="-0.014 0.19 0"/>
    <parent link="torso"/>
    <child link="link1_manipDer"/>
  </joint>
  <!-- link 1 -->
  <link name="link1_manipDer">
    <collision>
      <origin rpy="0 0 0" xyz="0 0 0"/>
      <geometry>
        <mesh filename="package://mmdt_rat20/meshes/link_1.stl" scale="0.001 0.001 0.001"/>
      </geometry>
    </collision>
    <visual>
      <origin rpy="0 0 0" xyz="0 0 0"/>
      <geometry>
        <mesh filename="package://mmdt_rat20/meshes/link_1.stl" scale="0.001 0.001 0.001"/>
      </geometry>
      <material name="black"/>
    </visual>
    <inertial>
      <origin rpy="0 0 0" xyz="0.00023 0.00000 0.06223"/>
      <!--<origin xyz="0.00023 0.00000 -0.06377" rpy="0 0 0"/>-->
      <mass value="0.85644"/>
      <inertia ixx="1.0" ixy="0.0" ixz="0.0" iyy="1.0" iyz="0.0" izz="1.0"/>
      <!--<inertia ixx="0.00121064" ixy="0.0" ixz="0.00001100" iyy="0.00120886" iyz="0.0" izz="0.00038103" />-->
    </inertial>
  </link>
  <!-- Joint 1 -->
  <joint name="manipDer_joint1" type="revolute">
    <parent link="link1_manipDer"/>
    <child link="link2_manipDer"/>
    <origin rpy="0 0 0" xyz="0.0 0.0 0.126"/>
    <axis xyz="0 0 1"/>
    <limit effort="1000" lower="-1.570796327" upper="1.570796327" velocity="6.5"/>
    <dynamics damping="80"/>
  </joint>
  <transmission name="tran1_manipDer">
    <type>transmission_interface/SimpleTransmission</type>
    <joint name="manipDer_joint1">
      <hardwareInterface>EffortJointInterface</hardwareInterface>
    </joint>
    <actuator name="motor1_manipDer">
      <hardwareInterface>EffortJointInterface</hardwareInterface>
      <mechanicalReduction>1</mechanicalReduction>
    </actuator>
  </transmission>
  <!-- link  2 -->
  <link name="link2_manipDer">
    <collision>
      <origin rpy="0 0 0" xyz="0 0 0"/>
      <geometry>
        <mesh filename="package://mmdt_rat20/meshes/link_2.stl" scale="0.001 0.001 0.001"/>
      </geometry>
    </collision>
    <visual>
      <origin rpy="0 0 0" xyz="0 0 0"/>
      <geometry>
        <mesh filename="package://mmdt_rat20/meshes/link_2.stl" scale="0.001 0.001 0.001"/>
      </geometry>
      <material name="grey"/>
    </visual>
    <inertial>
      <origin rpy="0 0 0" xyz="0.00000 0.00080 0.03183"/>
      <!--<origin xyz="0.00000 -0.06820 -0.00117" rpy="0 0 0"/>-->
      <mass value="0.94658"/>
      <inertia ixx="1.0" ixy="0.0" ixz="0.0" iyy="1.0" iyz="0.0" izz="1.0"/>
      <!--<inertia ixx="0.00152547" ixy="0.0" ixz="0.0" iyy="0.00045954" iyz="-0.00001086" izz="0.00151740" />-->
    </inertial>
  </link>
  <!-- Joint 2 -->
  <joint name="manipDer_joint2" type="revolute">
    <parent link="link2_manipDer"/>
    <child link="link3_manipDer"/>
    <origin rpy="0 0 0" xyz="0.0 0.069 0.033"/>
    <axis xyz="0 1 0"/>
    <limit effort="1000" lower="-1.570796327" upper="1.570796327" velocity="6.5"/>
    <dynamics damping="80"/>
  </joint>
  <transmission name="tran2_manipDer">
    <type>transmission_interface/SimpleTransmission</type>
    <joint name="manipDer_joint2">
      <hardwareInterface>EffortJointInterface</hardwareInterface>
    </joint>
    <actuator name="motor2_manipDer">
      <hardwareInterface>EffortJointInterface</hardwareInterface>
      <mechanicalReduction>1</mechanicalReduction>
    </actuator>
  </transmission>
  <!-- link 3 -->
  <link name="link3_manipDer">
    <collision>
      <origin rpy="0 0 0" xyz="0 0 0"/>
      <geometry>
        <mesh filename="package://mmdt_rat20/meshes/link_3.stl" scale="0.001 0.001 0.001"/>
      </geometry>
    </collision>
    <visual>
      <origin rpy="0 0 0" xyz="0 0 0"/>
      <geometry>
        <mesh filename="package://mmdt_rat20/meshes/link_3.stl" scale="0.001 0.001 0.001"/>
      </geometry>
      <material name="black"/>
    </visual>
    <inertial>
      <origin rpy="0 0 0" xyz="0.01768 -0.06881 0.20524"/>
      <!--<origin xyz="-0.01232 -0.05731 -0.05876" rpy="0 0 0"/>-->
      <mass value="1.30260"/>
      <inertia ixx="1.0" ixy="0.0" ixz="0.0" iyy="1.0" iyz="0.0" izz="1.0"/>
      <!--<inertia ixx="0.01111021" ixy="0.00001331" ixz="-0.00134208" iyy="0.01046642" iyz="0.00016235" izz="0.00202081" />-->
    </inertial>
  </link>
  <!-- Joint 3 -->
  <joint name="manipDer_joint3" type="revolute">
    <parent link="link3_manipDer"/>
    <child link="link4_manipDer"/>
    <origin rpy="0 0 0" xyz="0.03000 -0.01150 0.26400"/>
    <axis xyz="0 1 0"/>
    <limit effort="1000" lower="-1.570796327" upper="1.570796327" velocity="6.5"/>
    <dynamics damping="80"/>
  </joint>
  <transmission name="tran3_manipDer">
    <type>transmission_interface/SimpleTransmission</type>
    <joint name="manipDer_joint3">
      <hardwareInterface>EffortJointInterface</hardwareInterface>
    </joint>
    <actuator name="motor3_manipDer">
      <hardwareInterface>EffortJointInterface</hardwareInterface>
      <mechanicalReduction>1</mechanicalReduction>
    </actuator>
  </transmission>
  <!-- link 4 -->
  <link name="link4_manipDer">
    <collision>
      <origin rpy="0 0 0" xyz="0 0 0"/>
      <geometry>
        <mesh filename="package://mmdt_rat20/meshes/link_4.stl" scale="0.001 0.001 0.001"/>
      </geometry>
    </collision>
    <visual>
      <origin rpy="0 0 0" xyz="0 0 0"/>
      <geometry>
        <mesh filename="package://mmdt_rat20/meshes/link_4.stl" scale="0.001 0.001 0.001"/>
      </geometry>
      <material name="Grey"/>
    </visual>
    <inertial>
      <origin rpy="0 0 0" xyz="0.12475 -0.05716 0.02979"/>
      <!--<origin xyz="-0.07025 0.00034 -0.00021" rpy="0 0 0"/>-->
      <mass value="1.15977"/>
      <inertia ixx="1.0" ixy="0.0" ixz="0.0" iyy="1.0" iyz="0.0" izz="1.0"/>
      <!--<inertia ixx="0.00096726" ixy="0.00004383" ixz="-0.00002771" iyy="0.00318801" iyz="0.00000627" izz="0.00341484" />-->
    </inertial>
  </link>
  <!-- Joint 4 -->
  <joint name="manipDer_joint4" type="revolute">
    <parent link="link4_manipDer"/>
    <child link="link5_manipDer"/>
    <origin rpy="0 0 0" xyz="0.19500 -0.05750 0.03000"/>
    <axis xyz="1 0 0"/>
    <limit effort="1000" lower="-1.570796327" upper="1.570796327" velocity="6.5"/>
    <dynamics damping="80"/>
  </joint>
  <transmission name="tran4_manipDer">
    <type>transmission_interface/SimpleTransmission</type>
    <joint name="manipDer_joint4">
      <hardwareInterface>EffortJointInterface</hardwareInterface>
    </joint>
    <actuator name="motor4_manipDer">
      <hardwareInterface>EffortJointInterface</hardwareInterface>
      <mechanicalReduction>1</mechanicalReduction>
    </actuator>
  </transmission>
  <!-- link 5 -->
  <link name="link5_manipDer">
    <collision>
      <origin rpy="0 0 0" xyz="0 0 0"/>
      <geometry>
        <mesh filename="package://mmdt_rat20/meshes/link_5.stl" scale="0.001 0.001 0.001"/>
      </geometry>
    </collision>
    <visual>
      <origin rpy="0 0 0" xyz="0 0 0"/>
      <geometry>
        <mesh filename="package://mmdt_rat20/meshes/link_5.stl" scale="0.001 0.001 0.001"/>
      </geometry>
      <material name="grey"/>
    </visual>
    <inertial>
      <origin rpy="0 0 0" xyz="0.05642 -0.00217 0.00002"/>
      <!--<origin xyz="-0.00658 -0.04717 0.00002" rpy="0 0 0"/>-->
      <mass value="0.44688"/>
      <inertia ixx="1.0" ixy="0.0" ixz="0.0" iyy="1.0" iyz="0.0" izz="1.0"/>
      <!--<inertia ixx="0.00030285" ixy="0.00000761" ixz="0.00000031" iyy="0.00022339" iyz="-0.00000001" izz="0.00039766" />-->
    </inertial>
  </link>
  <!-- Joint 5 -->
  <joint name="manipDer_joint5" type="revolute">
    <parent link="link5_manipDer"/>
    <child link="link6_manipDer"/>
    <origin rpy="0 0 0" xyz="0.06300 0.04500 0.00000"/>
    <axis xyz="0 1 0"/>
    <limit effort="1000" lower="-1.570796327" upper="1.570796327" velocity="6.5"/>
    <dynamics damping="80"/>
  </joint>
  <transmission name="tran5_manipDer">
    <type>transmission_interface/SimpleTransmission</type>
    <joint name="manipDer_joint5">
      <hardwareInterface>EffortJointInterface</hardwareInterface>
    </joint>
    <actuator name="motor5_manipDer">
      <hardwareInterface>EffortJointInterface</hardwareInterface>
      <mechanicalReduction>1</mechanicalReduction>
    </actuator>
  </transmission>
  <!-- link 6 -->
  <link name="link6_manipDer">
    <collision>
      <origin rpy="0 0 0" xyz="0 0 0"/>
      <geometry>
        <mesh filename="package://mmdt_rat20/meshes/link_6.stl" scale="0.001 0.001 0.001"/>
      </geometry>
    </collision>
    <visual>
      <origin rpy="0 0 0" xyz="0 0 0"/>
      <geometry>
        <mesh filename="package://mmdt_rat20/meshes/link_6.stl" scale="0.001 0.001 0.001"/>
      </geometry>
      <material name="grey"/>
    </visual>
    <inertial>
      <origin rpy="0 0 0" xyz="0.06831 -0.04457 0.00000"/>
      <!--<origin xyz="-0.05469 0.00043 0.00000" rpy="0 0 0"/>-->
      <mass value="0.43273"/>
      <inertia ixx="1.0" ixy="0.0" ixz="0.0" iyy="1.0" iyz="0.0" izz="1.0"/>
      <!--<inertia ixx="0.00021512" ixy="0.00001009" ixz="0.00000000" iyy="0.00042827" iyz="0.00000000" izz="0.00051436" />-->
    </inertial>
  </link>
  <!-- Joint 6 -->
  <joint name="manipDer_joint6" type="revolute">
    <parent link="link6_manipDer"/>
    <child link="end_link_manipDer"/>
    <origin rpy="0 0 0" xyz="0.12300 -0.04500 0.00000"/>
    <axis xyz="1 0 0"/>
    <limit effort="1000" lower="-1.570796327" upper="1.570796327" velocity="6.5"/>
    <dynamics damping="80"/>
  </joint>
  <transmission name="tran6_manipDer">
    <type>transmission_interface/SimpleTransmission</type>
    <joint name="manipDer_joint6">
      <hardwareInterface>EffortJointInterface</hardwareInterface>
    </joint>
    <actuator name="motor6_manipDer">
      <hardwareInterface>EffortJointInterface</hardwareInterface>
      <mechanicalReduction>1</mechanicalReduction>
    </actuator>
  </transmission>
  <!-- end link -->
  <link name="end_link_manipDer">
    <collision>
      <origin rpy="0 0 0" xyz="0 0 0"/>
      <geometry>
        <mesh filename="package://mmdt_rat20/meshes/end_link.stl" scale="0.001 0.001 0.001"/>
      </geometry>
    </collision>
    <visual>
      <origin rpy="0 0 0" xyz="0 0 0"/>
      <geometry>
        <mesh filename="package://mmdt_rat20/meshes/end_link.stl" scale="0.001 0.001 0.001"/>
      </geometry>
      <material name="grey"/>
    </visual>
    <inertial>
      <origin rpy="0 0 0" xyz="0.00337 0.00000 0.00000"/>
      <mass value="0.01919"/>
      <inertia ixx="1.0" ixy="0.0" ixz="0.0" iyy="1.0" iyz="0.0" izz="1.0"/>
      <!--<inertia ixx="0.00000938" ixy="0.0" ixz="0.0" iyy="0.00000338" iyz="0.0" izz="0.00000635" />-->
    </inertial>
  </link>



<!-- *************************** BRAZO IZQUIERDO ***************************** -->
<!-- *********************************************************************** -->


<joint name="world_fixedIzq" type="fixed">
    <origin rpy="1.57 -1.57 1.57" xyz="0.014 0.19 0"/>
    <parent link="torso"/>
    <child link="link1_manipIzq"/>
  </joint>
  <!-- link 7 -->
  <link name="link1_manipIzq">
    <collision>
      <origin rpy="0 0 0" xyz="0 0 0"/>
      <geometry>
        <mesh filename="package://mmdt_rat20/meshes/link_1.stl" scale="0.001 0.001 0.001"/>
      </geometry>
    </collision>
    <visual>
      <origin rpy="0 0 0" xyz="0 0 0"/>
      <geometry>
        <mesh filename="package://mmdt_rat20/meshes/link_1.stl" scale="0.001 0.001 0.001"/>
      </geometry>
      <material name="grey"/>
    </visual>
    <inertial>
      <origin rpy="0 0 0" xyz="0.00023 0.00000 0.06223"/>
      <!--<origin xyz="0.00023 0.00000 -0.06377" rpy="0 0 0"/>-->
      <mass value="0.85644"/>
      <inertia ixx="1.0" ixy="0.0" ixz="0.0" iyy="1.0" iyz="0.0" izz="1.0"/>
      <!--<inertia ixx="0.00121064" ixy="0.0" ixz="0.00001100" iyy="0.00120886" iyz="0.0" izz="0.00038103" />-->
    </inertial>
  </link>
  <!-- Joint 7 -->
  <joint name="manipIzq_joint1" type="revolute">
    <parent link="link1_manipIzq"/>
    <child link="link2_manipIzq"/>
    <origin rpy="0 0 0" xyz="0.0 0.0 0.126"/>
    <axis xyz="0 0 1"/>
    <limit effort="1000" lower="-1.570796327" upper="1.570796327" velocity="6.5"/>
    <dynamics damping="80"/>
  </joint>
  <transmission name="tran1_manipIzq">
    <type>transmission_interface/SimpleTransmission</type>
    <joint name="manipIzq_joint1">
      <hardwareInterface>EffortJointInterface</hardwareInterface>
    </joint>
    <actuator name="motor1_manipIzq">
      <hardwareInterface>EffortJointInterface</hardwareInterface>
      <mechanicalReduction>1</mechanicalReduction>
    </actuator>
  </transmission>
  <!-- link  8 -->
  <link name="link2_manipIzq">
    <collision>
      <origin rpy="0 0 0" xyz="0 0 0"/>
      <geometry>
        <mesh filename="package://mmdt_rat20/meshes/link_2.stl" scale="0.001 0.001 0.001"/>
      </geometry>
    </collision>
    <visual>
      <origin rpy="0 0 0" xyz="0 0 0"/>
      <geometry>
        <mesh filename="package://mmdt_rat20/meshes/link_2.stl" scale="0.001 0.001 0.001"/>
      </geometry>
      <material name="grey"/>
    </visual>
    <inertial>
      <origin rpy="0 0 0" xyz="0.00000 0.00080 0.03183"/>
      <!--<origin xyz="0.00000 -0.06820 -0.00117" rpy="0 0 0"/>-->
      <mass value="0.94658"/>
      <inertia ixx="1.0" ixy="0.0" ixz="0.0" iyy="1.0" iyz="0.0" izz="1.0"/>
      <!--<inertia ixx="0.00152547" ixy="0.0" ixz="0.0" iyy="0.00045954" iyz="-0.00001086" izz="0.00151740" />-->
    </inertial>
  </link>
  <!-- Joint 8 -->
  <joint name="manipIzq_joint2" type="revolute">
    <parent link="link2_manipIzq"/>
    <child link="link3_manipIzq"/>
    <origin rpy="0 0 0" xyz="0.0 0.069 0.033"/>
    <axis xyz="0 1 0"/>
    <limit effort="1000" lower="-1.570796327" upper="1.570796327" velocity="6.5"/>
    <dynamics damping="80"/>
  </joint>
  <transmission name="tran2_manipIzq">
    <type>transmission_interface/SimpleTransmission</type>
    <joint name="manipIzq_joint2">
      <hardwareInterface>EffortJointInterface</hardwareInterface>
    </joint>
    <actuator name="motor2_manipIzq">
      <hardwareInterface>EffortJointInterface</hardwareInterface>
      <mechanicalReduction>1</mechanicalReduction>
    </actuator>
  </transmission>
  <!-- link 9 -->
  <link name="link3_manipIzq">
    <collision>
      <origin rpy="0 0 0" xyz="0 0 0"/>
      <geometry>
        <mesh filename="package://mmdt_rat20/meshes/link_3.stl" scale="0.001 0.001 0.001"/>
      </geometry>
    </collision>
    <visual>
      <origin rpy="0 0 0" xyz="0 0 0"/>
      <geometry>
        <mesh filename="package://mmdt_rat20/meshes/link_3.stl" scale="0.001 0.001 0.001"/>
      </geometry>
      <material name="grey"/>
    </visual>
    <inertial>
      <origin rpy="0 0 0" xyz="0.01768 -0.06881 0.20524"/>
      <!--<origin xyz="-0.01232 -0.05731 -0.05876" rpy="0 0 0"/>-->
      <mass value="1.30260"/>
      <inertia ixx="1.0" ixy="0.0" ixz="0.0" iyy="1.0" iyz="0.0" izz="1.0"/>
      <!--<inertia ixx="0.01111021" ixy="0.00001331" ixz="-0.00134208" iyy="0.01046642" iyz="0.00016235" izz="0.00202081" />-->
    </inertial>
  </link>
  <!-- Joint 9 -->
  <joint name="manipIzq_joint3" type="revolute">
    <parent link="link3_manipIzq"/>
    <child link="link4_manipIzq"/>
    <origin rpy="0 0 0" xyz="0.03000 -0.01150 0.26400"/>
    <axis xyz="0 1 0"/>
    <limit effort="1000" lower="-1.570796327" upper="1.570796327" velocity="6.5"/>
    <dynamics damping="80"/>
  </joint>
  <transmission name="tran3_manipIzq">
    <type>transmission_interface/SimpleTransmission</type>
    <joint name="manipIzq_joint3">
      <hardwareInterface>EffortJointInterface</hardwareInterface>
    </joint>
    <actuator name="motor3_manipIzq">
      <hardwareInterface>EffortJointInterface</hardwareInterface>
      <mechanicalReduction>1</mechanicalReduction>
    </actuator>
  </transmission>
  <!-- link 10 -->
  <link name="link4_manipIzq">
    <collision>
      <origin rpy="0 0 0" xyz="0 0 0"/>
      <geometry>
        <mesh filename="package://mmdt_rat20/meshes/link_4.stl" scale="0.001 0.001 0.001"/>
      </geometry>
    </collision>
    <visual>
      <origin rpy="0 0 0" xyz="0 0 0"/>
      <geometry>
        <mesh filename="package://mmdt_rat20/meshes/link_4.stl" scale="0.001 0.001 0.001"/>
      </geometry>
      <material name="grey"/>
    </visual>
    <inertial>
      <origin rpy="0 0 0" xyz="0.12475 -0.05716 0.02979"/>
      <!--<origin xyz="-0.07025 0.00034 -0.00021" rpy="0 0 0"/>-->
      <mass value="1.15977"/>
      <inertia ixx="1.0" ixy="0.0" ixz="0.0" iyy="1.0" iyz="0.0" izz="1.0"/>
      <!--<inertia ixx="0.00096726" ixy="0.00004383" ixz="-0.00002771" iyy="0.00318801" iyz="0.00000627" izz="0.00341484" />-->
    </inertial>
  </link>
  <!-- Joint 10 -->
  <joint name="manipIzq_joint4" type="revolute">
    <parent link="link4_manipIzq"/>
    <child link="link5_manipIzq"/>
    <origin rpy="0 0 0" xyz="0.19500 -0.05750 0.03000"/>
    <axis xyz="1 0 0"/>
    <limit effort="1000" lower="-1.570796327" upper="1.570796327" velocity="6.5"/>
    <dynamics damping="80"/>
  </joint>
  <transmission name="tran4_manipIzq">
    <type>transmission_interface/SimpleTransmission</type>
    <joint name="manipIzq_joint4">
      <hardwareInterface>EffortJointInterface</hardwareInterface>
    </joint>
    <actuator name="motor4_manipIzq">
      <hardwareInterface>EffortJointInterface</hardwareInterface>
      <mechanicalReduction>1</mechanicalReduction>
    </actuator>
  </transmission>
  <!-- link 11 -->
  <link name="link5_manipIzq">
    <collision>
      <origin rpy="0 0 0" xyz="0 0 0"/>
      <geometry>
        <mesh filename="package://mmdt_rat20/meshes/link_5.stl" scale="0.001 0.001 0.001"/>
      </geometry>
    </collision>
    <visual>
      <origin rpy="0 0 0" xyz="0 0 0"/>
      <geometry>
        <mesh filename="package://mmdt_rat20/meshes/link_5.stl" scale="0.001 0.001 0.001"/>
      </geometry>
      <material name="grey"/>
    </visual>
    <inertial>
      <origin rpy="0 0 0" xyz="0.05642 -0.00217 0.00002"/>
      <!--<origin xyz="-0.00658 -0.04717 0.00002" rpy="0 0 0"/>-->
      <mass value="0.44688"/>
      <inertia ixx="1.0" ixy="0.0" ixz="0.0" iyy="1.0" iyz="0.0" izz="1.0"/>
      <!--<inertia ixx="0.00030285" ixy="0.00000761" ixz="0.00000031" iyy="0.00022339" iyz="-0.00000001" izz="0.00039766" />-->
    </inertial>
  </link>
  <!-- Joint 11 -->
  <joint name="manipIzq_joint5" type="revolute">
    <parent link="link5_manipIzq"/>
    <child link="link6_manipIzq"/>
    <origin rpy="0 0 0" xyz="0.06300 0.04500 0.00000"/>
    <axis xyz="0 1 0"/>
    <limit effort="1000" lower="-1.570796327" upper="1.570796327" velocity="6.5"/>
    <dynamics damping="80"/>
  </joint>
  <transmission name="tran5_manipIzq">
    <type>transmission_interface/SimpleTransmission</type>
    <joint name="manipIzq_joint5">
      <hardwareInterface>EffortJointInterface</hardwareInterface>
    </joint>
    <actuator name="motor5_manipIzq">
      <hardwareInterface>EffortJointInterface</hardwareInterface>
      <mechanicalReduction>1</mechanicalReduction>
    </actuator>
  </transmission>
  <!-- link 12 -->
  <link name="link6_manipIzq">
    <collision>
      <origin rpy="0 0 0" xyz="0 0 0"/>
      <geometry>
        <mesh filename="package://mmdt_rat20/meshes/link_6.stl" scale="0.001 0.001 0.001"/>
      </geometry>
    </collision>
    <visual>
      <origin rpy="0 0 0" xyz="0 0 0"/>
      <geometry>
        <mesh filename="package://mmdt_rat20/meshes/link_6.stl" scale="0.001 0.001 0.001"/>
      </geometry>
      <material name="grey"/>
    </visual>
    <inertial>
      <origin rpy="0 0 0" xyz="0.06831 -0.04457 0.00000"/>
      <!--<origin xyz="-0.05469 0.00043 0.00000" rpy="0 0 0"/>-->
      <mass value="0.43273"/>
      <inertia ixx="1.0" ixy="0.0" ixz="0.0" iyy="1.0" iyz="0.0" izz="1.0"/>
      <!--<inertia ixx="0.00021512" ixy="0.00001009" ixz="0.00000000" iyy="0.00042827" iyz="0.00000000" izz="0.00051436" />-->
    </inertial>
  </link>
  <!-- Joint 12 -->
  <joint name="manipIzq_joint6" type="revolute">
    <parent link="link6_manipIzq"/>
    <child link="end_link_manipIzq"/>
    <origin rpy="0 0 0" xyz="0.12300 -0.04500 0.00000"/>
    <axis xyz="1 0 0"/>
    <limit effort="1000" lower="-1.570796327" upper="1.570796327" velocity="6.5"/>
    <dynamics damping="80"/>
  </joint>
  <transmission name="tran6_manipIzq">
    <type>transmission_interface/SimpleTransmission</type>
    <joint name="manipIzq_joint6">
      <hardwareInterface>EffortJointInterface</hardwareInterface>
    </joint>
    <actuator name="motor6_manipIzq">
      <hardwareInterface>EffortJointInterface</hardwareInterface>
      <mechanicalReduction>1</mechanicalReduction>
    </actuator>
  </transmission>
  <!-- end link1 -->
  <link name="end_link_manipIzq">
    <collision>
      <origin rpy="0 0 0" xyz="0 0 0"/>
      <geometry>
        <mesh filename="package://mmdt_rat20/meshes/end_link.stl" scale="0.001 0.001 0.001"/>
      </geometry>
    </collision>
    <visual>
      <origin rpy="0 0 0" xyz="0 0 0"/>
      <geometry>
        <mesh filename="package://mmdt_rat20/meshes/end_link.stl" scale="0.001 0.001 0.001"/>
      </geometry>
      <material name="grey"/>
    </visual>
    <inertial>
      <origin rpy="0 0 0" xyz="0.00337 0.00000 0.00000"/>
      <mass value="0.01919"/>
      <inertia ixx="1.0" ixy="0.0" ixz="0.0" iyy="1.0" iyz="0.0" izz="1.0"/>
      <!--<inertia ixx="0.00000938" ixy="0.0" ixz="0.0" iyy="0.00000338" iyz="0.0" izz="0.00000635" />-->
    </inertial>
  </link>




<!-- PARTE DEL LASER -->
<!-- Hay que considerar que esta rotado para encajar con el modelo dado por Leopoldo -->
  <!-- <joint name="hokuyo_joint" type="fixed">
  <axis xyz="1 0 0" />
  <origin xyz="-0.25 0.01 0" rpy="1.5708 3.14 0"/>
  <parent link="chasis"/>
  <child link="hokuyo"/>
  </joint>

  <link name="hokuyo">
  <collision>
    <origin xyz="0 0 0" rpy="0 0 0"/>
    <geometry>
  <box size="0.03 0.03 0.03"/>
    </geometry>
  </collision>

  <visual>
    <origin xyz="0 0 0" rpy="0 0 0"/>
    <geometry>
      <mesh filename="package://mmdt_rat20/meshes/hokuyo.dae"/>
    </geometry>
  </visual>

  <inertial>
    <mass value="1e-3" />
    <origin xyz="0 0 0" rpy="0 0 0"/>
    <inertia ixx="1e-6" ixy="0" ixz="0" iyy="1e-6" iyz="0" izz="1e-6" />
  </inertial>
  </link> -->


<!-- PARTE DE LA IMU -->
<!-- Hay que considerar que esta rotado para encajar con el modelo dado por Leopoldo -->
  <!-- <joint name="IMU_joint" type="fixed">
  <axis xyz="1 0 0" />
  <origin xyz="0.2 0.06 0" rpy="1.5708 3.14 0"/>
  <parent link="chasis"/>
  <child link="IMU"/>
  </joint>

  <link name="IMU">
  <collision>
    <origin xyz="0 0 0" rpy="0 0 0"/>
    <geometry>
    <box size="0.1 0.05 0.01"/>
    </geometry>
  </collision>

  <visual>
    <origin xyz="0 0 0" rpy="0 0 0"/>
    <geometry>
      <box size="0.1 0.05 0.01"/>
    </geometry>
  </visual>

  <inertial>
    <mass value="1e-5" />
    <origin xyz="0 0 0" rpy="0 0 0"/>
    <inertia ixx="1e-6" ixy="0" ixz="0" iyy="1e-6" iyz="0" izz="1e-6" />
  </inertial>
  </link> -->

  <!-- PARTE DE LA CAMARITA -->
  <!-- <joint name="cameraTop_joint" type="fixed">
    <axis xyz="0 0 0" />
    <origin xyz="-0.3 -1.2 0.0" rpy="1.57 3.14 -1.57"/>
    <parent link="chasis"/>
    <child link="cameraTop_link"/>
  </joint> -->

  <joint name="cameraTop_joint" type="fixed">
    <axis xyz="0 0 0" />
    <!-- <origin xyz="0 0.30 -0.12" rpy="-1.57 -1.57 0"/> -->
    <origin xyz="0 0.25 0.03" rpy="-1.57 -1.57 0.0"/>
    <!-- <parent link="chasis"/> -->
    <parent link="torso"/>
    <child link="cameraTop_link"/>
  </joint>

<!-- Camara de arriba: -->
  <joint name="cameraSide_joint" type="fixed">
    <axis xyz="0 0 0" />
    <origin xyz="-0.5 -1.2 0.0" rpy="1.57 3.14 -1.57"/>
    <parent link="chasis"/>
    <child link="cameraSide_link"/>
  </joint>

  <!-- <joint name="cameraSide_joint" type="fixed">
    <axis xyz="0 0 0" />
    <origin xyz="-0.5 -0.3 0.9" rpy="1.57 1.57 0"/>
    <parent link="chasis"/>
    <child link="cameraSide_link"/>
  </joint> -->

  <!-- Cameras -->
  <link name="cameraTop_link">
    <!-- <collision>
      <origin xyz="0 0 0" rpy="0 0 0"/>
      <geometry>
    <box size="0.01 0.05 0.05"/>
      </geometry>
    </collision> -->

    <visual>
      <origin xyz="0 0 0" rpy="0 0 0"/>
      <geometry>
    <box size="0.01 0.04 0.08"/>
      </geometry>
      <material name="red"/>
    </visual>

    <!-- <inertial>
      <mass value="1e-5" />
      <origin xyz="0 0 0" rpy="0 0 0"/>
      <inertia ixx="1e-6" ixy="0" ixz="0" iyy="1e-6" iyz="0" izz="1e-6" />
    </inertial> -->
  </link>

  <link name="cameraSide_link">
    <!-- <collision>
      <origin xyz="0 0 0" rpy="0 0 0"/>
      <geometry>
    <box size="0.01 0.05 0.05"/>
      </geometry>
    </collision> -->

    <visual>
      <origin xyz="0 0 0" rpy="0 0 0"/>
      <geometry>
    <box size="0.01 0.04 0.08"/>
      </geometry>
      <material name="red"/>
    </visual>

    <!-- <inertial>
      <mass value="1e-5" />
      <origin xyz="0 0 0" rpy="0 0 0"/>
      <inertia ixx="1e-6" ixy="0" ixz="0" iyy="1e-6" iyz="0" izz="1e-6" />
    </inertial> -->
  </link>

<!-- Dandole colorcito a todo! -->

<!-- Las fricciones puestas en las ruedas corresponden al tipo de material de la rueda y el piso,
      dependiendo de aquello se seleccionan las fricciones mu1 (estatica), mu2 (cinetica-deslizamiento);
      todas son tomadas de la pagina:
      https://www.engineeringtoolbox.com/friction-coefficients-d_778.html,
      http://ffden-2.phys.uaf.edu/211_fall2002.web.dir/ben_townsend/staticandkineticfriction.htm
      http://www.ode.org/ode-latest-userguide.html#sec_7_3_7

      Por ejemplo: para unas ruedas de goma, interactuando con asfalto limpio y seco: mu1:0.9, mu2:0.8-->
      <!-- Rueda de auto en asfalto seco: mu1:0.72, mu2:0 -->
      <!-- Rueda de auto en cesped: mu1:0.35, mu2:0 -->

<!-- <property name="mu_dado" value="10000" />
<property name="mu2_dado" value="10000" /> -->


  <gazebo reference="cameraTop_link">
    <material value="Gazebo/Green"/>
    <selfCollide>true</selfCollide>
  </gazebo>

  <gazebo reference="cameraSide_link">
    <material value="Gazebo/Green"/>
    <selfCollide>true</selfCollide>
  </gazebo>

  <gazebo reference="chasis">
    <material value="Gazebo/Gold "/>
    <selfCollide>true</selfCollide>
  </gazebo>

  <gazebo reference="torso">
    <material value="Gazebo/Gold "/>
    <selfCollide>true</selfCollide>
  </gazebo>

  <gazebo reference="baseTorso">
    <material value="Gazebo/DarkGrey"/>
    <selfCollide>true</selfCollide>
  </gazebo>

  <gazebo reference="link1_manipDer">
    <material value="Gazebo/Gold"/>
    <selfCollide>true</selfCollide>
  </gazebo>
  <gazebo reference="link2_manipDer">
    <material value="Gazebo/DarkGrey"/>
    <selfCollide>true</selfCollide>
  </gazebo>
  <gazebo reference="link3_manipDer">
    <material value="Gazebo/DarkGrey"/>
    <selfCollide>true</selfCollide>
  </gazebo>
  <gazebo reference="link4_manipDer">
    <material value="Gazebo/DarkGrey"/>
    <selfCollide>true</selfCollide>
  </gazebo>
  <gazebo reference="link5_manipDer">
    <material value="Gazebo/DarkGrey"/>
    <selfCollide>true</selfCollide>
  </gazebo>

  <gazebo reference="link6_manipDer">
    <material value="Gazebo/DarkGrey"/>
    <selfCollide>true</selfCollide>
  </gazebo>

  <gazebo reference="end_link_manipDer">
    <material value="Gazebo/Red"/>
    <selfCollide>true</selfCollide>
  </gazebo>

  <gazebo reference="link1_manipIzq">
    <material value="Gazebo/Gold"/>
    <selfCollide>true</selfCollide>
  </gazebo>
  
  <gazebo reference="link2_manipIzq">
    <material value="Gazebo/DarkGrey"/>
    <selfCollide>true</selfCollide>
  </gazebo>

  <gazebo reference="link3_manipIzq">
    <material value="Gazebo/DarkGrey"/>
    <selfCollide>true</selfCollide>
  </gazebo>

  <gazebo reference="link4_manipIzq">
    <material value="Gazebo/DarkGrey"/>
    <selfCollide>true</selfCollide>
  </gazebo>

  <gazebo reference="link5_manipIzq">
    <material value="Gazebo/DarkGrey"/>
    <selfCollide>true</selfCollide>
  </gazebo>

  <gazebo reference="link6_manipIzq">
    <material value="Gazebo/DarkGrey"/>
    <selfCollide>true</selfCollide>
  </gazebo>

  <gazebo reference="end_link_manipIzq">
    <material value="Gazebo/Red"/>
    <selfCollide>true</selfCollide>
  </gazebo>
  <!-- <gazebo reference="IMU">
    <material value="Gazebo/Green"/>
  </gazebo>  -->


  <!-- Gazebo plugin for ROS Control -->
  <gazebo>
    <plugin name="gazebo_ros_control" filename="libgazebo_ros_control.so">
      <robotNamespace>/mmdt_rat20</robotNamespace>
      <robotSimType>gazebo_ros_control/DefaultRobotHWSim</robotSimType>
    </plugin>
  </gazebo>


  <!-- Sensor Laser hokuyo -->
  <!-- <gazebo reference="hokuyo">
    <sensor type="gpu_ray" name="head_hokuyo_sensor">
      <pose>0 0 0 0 0 0</pose>
      <visualize>true</visualize>
      <update_rate>100</update_rate>
      <ray>
        <scan>
          <horizontal>
            <samples>128</samples>
            <resolution>1</resolution>
            <min_angle>-1.570796</min_angle>
            <max_angle>1.570796</max_angle>
          </horizontal>
        </scan>
        <range>
          <min>0.10</min>
          <max>4.0</max>
          <resolution>0.01</resolution>
        </range>
        <noise>
          <type>gaussian</type>

          <mean>0.0</mean>
          <stddev>0.01</stddev>
        </noise>
      </ray>
      <plugin name="gazebo_ros_head_hokuyo_controller" filename="libgazebo_ros_gpu_laser.so">
        <topicName>/mmdt_rat20/laser/scan</topicName>
        <frameName>hokuyo_link</frameName>
      </plugin>
    </sensor>
  </gazebo> -->
            <!-- Noise parameters based on published spec for Hokuyo laser
               achieving "+-30mm" accuracy at range < 10m.  A mean of 0.0m and
               stddev of 0.01m will put 99.7% of samples within 0.03m of the true
               reading. -->

  <!-- <gazebo reference="IMU">
    <gravity>true</gravity>
    <sensor name="imu_sensor" type="imu">
      <always_on>true</always_on>
      <update_rate>100</update_rate>
      <visualize>true</visualize>
      <topic>__default_topic__</topic>
      <plugin filename="libgazebo_ros_imu_sensor.so" name="imu_plugin">
        <topicName>/mmdt_rat20/imu</topicName>
        <bodyName>IMU</bodyName>
        <updateRateHZ>100.0</updateRateHZ>
        <gaussianNoise>0.0</gaussianNoise>
        <xyzOffset>0 0 0</xyzOffset>
        <rpyOffset>0 0 0</rpyOffset>
        <frameName>IMU</frameName>
        <initialOrientationAsReference>false</initialOrientationAsReference>
      </plugin>
      <pose>0 0 0 0 0 0</pose>
    </sensor>
  </gazebo> -->


<!-- camera -->
  <gazebo reference="cameraTop_link">
    <sensor type="camera" name="cameraTop">
      <update_rate>30.0</update_rate>
      <camera name="head">
        <horizontal_fov>1.9962634</horizontal_fov>
        <image>
          <width>1000</width>
          <height>600</height>
          <format>R8G8B8</format>
        </image>
        <clip>
          <near>0.02</near>
          <far>300</far>
        </clip>
        <noise>
          <type>gaussian</type>
          <!-- Noise is sampled independently per pixel on each frame.
               That pixel's noise value is added to each of its color
               channels, which at that point lie in the range [0,1]. -->
          <mean>0.0</mean>
          <stddev>0.007</stddev>
        </noise>
      </camera>
      <plugin name="camera_controller" filename="libgazebo_ros_camera.so">
        <alwaysOn>true</alwaysOn>
        <updateRate>0.0</updateRate>
        <cameraName>mmdt_rat20/cameraTop</cameraName>
        <imageTopicName>image_raw</imageTopicName>
        <cameraInfoTopicName>camera_info</cameraInfoTopicName>
        <frameName>cameraTop_link</frameName>
        <hackBaseline>0.07</hackBaseline>
        <distortionK1>0.0</distortionK1>
        <distortionK2>0.0</distortionK2>
        <distortionK3>0.0</distortionK3>
        <distortionT1>0.0</distortionT1>
        <distortionT2>0.0</distortionT2>
      </plugin>
    </sensor>
  </gazebo>

  <gazebo reference="cameraSide_link">
    <sensor type="camera" name="cameraSide">
      <update_rate>10.0</update_rate>
      <camera name="head">
        <horizontal_fov>1.3962634</horizontal_fov>
        <image>
          <width>300</width>
          <height>300</height>
          <format>R8G8B8</format>
        </image>
        <clip>
          <near>0.02</near>
          <far>300</far>
        </clip>
        <noise>
          <type>gaussian</type>
          <!-- Noise is sampled independently per pixel on each frame.
               That pixel's noise value is added to each of its color
               channels, which at that point lie in the range [0,1]. -->
          <mean>0.0</mean>
          <stddev>0.007</stddev>
        </noise>
      </camera>
      <plugin name="camera_controller" filename="libgazebo_ros_camera.so">
        <alwaysOn>true</alwaysOn>
        <updateRate>0.0</updateRate>
        <cameraName>mmdt_rat20/cameraSide</cameraName>
        <imageTopicName>image_raw</imageTopicName>
        <cameraInfoTopicName>camera_info</cameraInfoTopicName>
        <frameName>cameraSide_link</frameName>
        <hackBaseline>0.07</hackBaseline>
        <distortionK1>0.0</distortionK1>
        <distortionK2>0.0</distortionK2>
        <distortionK3>0.0</distortionK3>
        <distortionT1>0.0</distortionT1>
        <distortionT2>0.0</distortionT2>
      </plugin>
    </sensor>
  </gazebo>

</robot>